Workbook

Sheet Станд.норм.распр.
A1: Эксперимент | B1: 1 | C1: 2 | D1: 3 | E1: 4 | F1: 5 | G1: 6 | H1: 7 | I1: 8 | J1: 9 | K1: 10
A3: u 1 | B3: -0.028117029 | C3: -1.7017146 | D3: -0.54151542 | E3: 0.39923748 | F3: -0.94007953 | G3: 0.38157054 | H3: 0.88259867 | I3: -2.1222695 | J3: 0.81152166 | K3: -0.94664074
A4: u 2 | B4: -0.13377303 | C4: 2.0590323 | D4: 2.0433617 | E4: 1.3031877 | F4: 0.7844892 | G4: -0.91560423 | H4: -0.85754288 | I4: 0.65159156 | J4: 0.046873083 | K4: 0.70356464
A5: u 3 | B5: -0.63859375 | C5: -0.3852756 | D5: 0.93473318 | E5: 2.0791958 | F5: 0.37335553 | G5: -0.051544475 | H5: 1.2979914 | I5: -1.1267821 | J5: -1.0132885 | K5: -0.70180135
A6: u 4 | B6: -0.8930374 | C6: 2.1438609 | D6: -0.027810074 | E6: -0.3047171 | F6: 0.31965556 | G6: 0.29152034 | H6: 2.2457425 | I6: 0.31057198 | J6: 0.068787358 | K6: 0.044192348
A7: u 5 | B7: 0.0040154191 | C7: 0.06924779 | D7: 0.46304763 | E7: -0.036918664 | F7: 0.21292522 | G7: -0.088125489 | H7: -0.26654561 | I7: 0.36655592 | J7: 0.042481017 | K7: 1.5348496
A8: u 6 | B8: -0.82779252 | C8: -1.8222136 | D8: 0.5788354 | E8: -0.94233883 | F8: 0.60233333 | G8: 0.19098593 | H8: -0.20940547 | I8: -0.79693336 | J8: -0.84111889 | K8: 0.91711854
A9: u 7 | B9: 1.2953592 | C9: -0.9172345 | D9: 0.90196181 | E9: 1.1392831 | F9: 0.25269969 | G9: -0.072699322 | H9: 0.57612397 | I9: 0.61587002 | J9: 0.7434187 | K9: 0.19737854
A10: u 8 | B10: 0.33288757 | C10: -2.1625056 | D10: -0.72717967 | E10: 0.44566036 | F10: 0.024519977 | G10: 1.8059563 | H10: 1.3853037 | I10: 0.2911213 | J10: 0.83073098 | K10: -1.1263501
A11: u 9 | B11: 0.69564976 | C11: -0.27535407 | D11: -0.67283395 | E11: 0.0439627 | F11: -0.24567612 | G11: 1.0691952 | H11: 1.3251383 | I11: 0.79756546 | J11: 1.13243 | K11: 0.34276809
A12: u 10 | B12: 0.26551561 | C12: -2.1453798 | D12: 0.51032885 | E12: 1.5016667 | F12: 0.57170382 | G12: 0.92765276 | H12: 2.5883492 | I12: 1.1947486 | J12: 0.095346877 | K12: -0.29367584
A13: u 11 | B13: -0.2355182 | C13: -0.946402 | D13: -0.064801498 | E13: -0.58345449 | F13: 0.55199735 | G13: -0.85239662 | H13: 0.21167352 | I13: 2.4379551 | J13: -0.4101139 | K13: -0.12536475
... A102: u 100 | B102: 1.6609 | C102: -0.22880272 | D102: -1.8118356 | E102: 1.4537984 | F102: -1.1155979 | G102: -0.93441155 | H102: 0.96174753 | I102: 0.12693101 | J102: -1.722188 | K102: 0.32271381

Sheet Задание
A1: Спецификация | B1: Y=а0+а1*X | I1: Провести расчеты для каждого из случаев:
A2: а0= | B2: 14 | C2: X1 | D2: = | E2: 212 | F2: Y1 | G2: = | H2: =$B$2 + $B$3*E2 -> 2346 | J2: а. Выполнение всех предпосылок теоремы Гаусса-Маркова
A3: а1= | B3: 11 | C3: X2 | D3: = | E3: 780 | F3: Y2 | G3: = | H3: =$B$2 + $B$3*E3 -> 8594 | J3: б. Нарушение предпосылки о нулевом математическом ожидании остатков
A4: сигма= | B4: 9 | C4: X3 | D4: = | E4: 280 | F4: Y3 | G4: = | H4: =$B$2 + $B$3*E4 -> 3094 | J4: в. Нарушение предпосылки о гомоскедастичности остатков
C5: X4 | D5: = | E5: 888 | F5: Y4 | G5: = | H5: =$B$2 + $B$3*E5 -> 9782 | J5: г. Нарушение предпосылки о некоррелированности остатков
C6: X5 | D6: = | E6: 314 | F6: Y5 | G6: = | H6: =$B$2 + $B$3*E6 -> 3468 | J6: д. Нарушение предпосылки о некоррелированности значений экзогенной переменной и остатков
C7: X6 | D7: = | E7: 780 | F7: Y6 | G7: = | H7: =$B$2 + $B$3*E7 -> 8594
C8: X7 | D8: = | E8: 993 | F8: Y7 | G8: = | H8: =$B$2 + $B$3*E8 -> 10937 | I8: 1. Записать на основе функциональной зависимости спецификацию корреляционной зависимости с требуемыми характеристиками
C9: X8 | D9: = | E9: 326 | F9: Y8 | G9: = | H9: =$B$2 + $B$3*E9 -> 3600 | I9: 2. Имитировать данные для оценивания методом статистических испытаний Монте-Карло и на их основе оценить параметры модели
C10: X9 | D10: = | E10: 906 | F10: Y9 | G10: = | H10: =$B$2 + $B$3*E10 -> 9980 | I10: 3. Проанализровать результаты оценивания параметров модели и написать вывод
C11: X10 | D11: = | E11: 790 | F11: Y10 | G11: = | H11: =$B$2 + $B$3*E11 -> 8704
C12: X11 | D12: = | E12: 127 | F12: Y11 | G12: = | H12: =$B$2 + $B$3*E12 -> 1411
C13: X12 | D13: = | E13: 685 | F13: Y12 | G13: = | H13: =$B$2 + $B$3*E13 -> 7549
C14: X13 | D14: = | E14: 320 | F14: Y13 | G14: = | H14: =$B$2 + $B$3*E14 -> 3534 | I14: Примечание:
C15: X14 | D15: = | E15: 658 | F15: Y14 | G15: = | H15: =$B$2 + $B$3*E15 -> 7252 | I15: В каждом случае провести 10 экспериментов.
C16: X15 | D16: = | E16: 436 | F16: Y15 | G16: = | H16: =$B$2 + $B$3*E16 -> 4810 | I16: Расчеты для каждого пункта выполнить на отдельном листе.
C17: X16 | D17: = | E17: 686 | F17: Y16 | G17: = | H17: =$B$2 + $B$3*E17 -> 7560
C18: X17 | D18: = | E18: 797 | F18: Y17 | G18: = | H18: =$B$2 + $B$3*E18 -> 8781
C19: X18 | D19: = | E19: 464 | F19: Y18 | G19: = | H19: =$B$2 + $B$3*E19 -> 5118 | I19: {=LINEST(H2:H101,E2:E101,1,1)} -> 11 | J19: 14
C20: X19 | D20: = | E20: 514 | F20: Y19 | G20: = | H20: =$B$2 + $B$3*E20 -> 5668 | I20: 5.6156876e-16 | J20: 3.3636264e-13
C21: X20 | D21: = | E21: 724 | F21: Y20 | G21: = | H21: =$B$2 + $B$3*E21 -> 7978 | I21: 1 | J21: 1.5453857e-12
C22: X21 | D22: = | E22: 63 | F22: Y21 | G22: = | H22: =$B$2 + $B$3*E22 -> 707 | I22: 3.8368913e+32 | J22: 98
C23: X22 | D23: = | E23: 298 | F23: Y22 | G23: = | H23: =$B$2 + $B$3*E23 -> 3292 | I23: 9.1633288e+08 | J23: 2.3404526e-22
C24: X23 | D24: = | E24: 689 | F24: Y23 | G24: = | H24: =$B$2 + $B$3*E24 -> 7593
C25: X24 | D25: = | E25: 278 | F25: Y24 | G25: = | H25: =$B$2 + $B$3*E25 -> 3072
C26: X25 | D26: = | E26: 701 | F26: Y25 | G26: = | H26: =$B$2 + $B$3*E26 -> 7725
C27: X26 | D27: = | E27: 219 | F27: Y26 | G27: = | H27: =$B$2 + $B$3*E27 -> 2423
C28: X27 | D28: = | E28: 666 | F28: Y27 | G28: = | H28: =$B$2 + $B$3*E28 -> 7340
C29: X28 | D29: = | E29: 92 | F29: Y28 | G29: = | H29: =$B$2 + $B$3*E29 -> 1026
C30: X29 | D30: = | E30: 250 | F30: Y29 | G30: = | H30: =$B$2 + $B$3*E30 -> 2764
C31: X30 | D31: = | E31: 252 | F31: Y30 | G31: = | H31: =$B$2 + $B$3*E31 -> 2786
C32: X31 | D32: = | E32: 110 | F32: Y31 | G32: = | H32: =$B$2 + $B$3*E32 -> 1224
C33: X32 | D33: = | E33: 185 | F33: Y32 | G33: = | H33: =$B$2 + $B$3*E33 -> 2049
C34: X33 | D34: = | E34: 281 | F34: Y33 | G34: = | H34: =$B$2 + $B$3*E34 -> 3105
C35: X34 | D35: = | E35: 315 | F35: Y34 | G35: = | H35: =$B$2 + $B$3*E35 -> 3479
... C101: X100 | D101: = | E101: 629 | F101: Y100 | G101: = | H101: =$B$2 + $B$3*E101 -> 6933

Sheet 1.
A1: Ui = ui * сигма | H1: 1 экс | I1: 2 экс | J1: 3 экс | K1: 4 экс | L1: 5 экс | M1: 6 экс | N1: 7 экс | O1: 8 экс | P1: 9 экс | Q1: 10 экс
A2: а0= | B2: 14 | C2: X1 | D2: = | E2: 212 | F2: Y1 | G2: = | H2: =$B$2 + $B$3*E2 + 'Станд.норм.распр.'!B3 * $B$4 -> 2345.7469 | I2: =$B$2 + $B$3*E2 + 'Станд.норм.распр.'!C3 * $B$4 -> 2330.6846 | J2: =$B$2 + $B$3*E2 + 'Станд.норм.распр.'!D3 * $B$4 -> 2341.1264 | K2: =$B$2 + $B$3*E2 + 'Станд.норм.распр.'!E3 * $B$4 -> 2349.5931 | L2: =$B$2 + $B$3*E2 + 'Станд.норм.распр.'!F3 * $B$4 -> 2337.5393 | M2: =$B$2 + $B$3*E2 + 'Станд.норм.распр.'!G3 * $B$4 -> 2349.4341 | N2: =$B$2 + $B$3*E2 + 'Станд.норм.распр.'!H3 * $B$4 -> 2353.9434 | O2: =$B$2 + $B$3*E2 + 'Станд.норм.распр.'!I3 * $B$4 -> 2326.8996 | P2: =$B$2 + $B$3*E2 + 'Станд.норм.распр.'!J3 * $B$4 -> 2353.3037 | Q2: =$B$2 + $B$3*E2 + 'Станд.норм.распр.'!K3 * $B$4 -> 2337.4802
A3: а1= | B3: 11 | C3: X2 | D3: = | E3: 780 | F3: Y2 | G3: = | H3: =$B$2 + $B$3*E3 + 'Станд.норм.распр.'!B4 * $B$4 -> 8592.796 | I3: =$B$2 + $B$3*E3 + 'Станд.норм.распр.'!C4 * $B$4 -> 8612.5313 | J3: =$B$2 + $B$3*E3 + 'Станд.норм.распр.'!D4 * $B$4 -> 8612.3903 | K3: =$B$2 + $B$3*E3 + 'Станд.норм.распр.'!E4 * $B$4 -> 8605.7287 | L3: =$B$2 + $B$3*E3 + 'Станд.норм.распр.'!F4 * $B$4 -> 8601.0604 | M3: =$B$2 + $B$3*E3 + 'Станд.норм.распр.'!G4 * $B$4 -> 8585.7596 | N3: =$B$2 + $B$3*E3 + 'Станд.норм.распр.'!H4 * $B$4 -> 8586.2821 | O3: =$B$2 + $B$3*E3 + 'Станд.норм.распр.'!I4 * $B$4 -> 8599.8643 | P3: =$B$2 + $B$3*E3 + 'Станд.норм.распр.'!J4 * $B$4 -> 8594.4219 | Q3: =$B$2 + $B$3*E3 + 'Станд.норм.распр.'!K4 * $B$4 -> 8600.3321
A4: сигма= | B4: 9 | C4: X3 | D4: = | E4: 280 | F4: Y3 | G4: = | H4: =$B$2 + $B$3*E4 + 'Станд.норм.распр.'!B5 * $B$4 -> 3088.2527 | I4: =$B$2 + $B$3*E4 + 'Станд.норм.распр.'!C5 * $B$4 -> 3090.5325 | J4: =$B$2 + $B$3*E4 + 'Станд.норм.распр.'!D5 * $B$4 -> 3102.4126 | K4: =$B$2 + $B$3*E4 + 'Станд.норм.распр.'!E5 * $B$4 -> 3112.7128 | L4: =$B$2 + $B$3*E4 + 'Станд.норм.распр.'!F5 * $B$4 -> 3097.3602 | M4: =$B$2 + $B$3*E4 + 'Станд.норм.распр.'!G5 * $B$4 -> 3093.5361 | N4: =$B$2 + $B$3*E4 + 'Станд.норм.распр.'!H5 * $B$4 -> 3105.6819 | O4: =$B$2 + $B$3*E4 + 'Станд.норм.распр.'!I5 * $B$4 -> 3083.859 | P4: =$B$2 + $B$3*E4 + 'Станд.норм.распр.'!J5 * $B$4 -> 3084.8804 | Q4: =$B$2 + $B$3*E4 + 'Станд.норм.распр.'!K5 * $B$4 -> 3087.6838
C5: X4 | D5: = | E5: 888 | F5: Y4 | G5: = | H5: =$B$2 + $B$3*E5 + 'Станд.норм.распр.'!B6 * $B$4 -> 9773.9627 | I5: =$B$2 + $B$3*E5 + 'Станд.норм.распр.'!C6 * $B$4 -> 9801.2947 | J5: =$B$2 + $B$3*E5 + 'Станд.норм.распр.'!D6 * $B$4 -> 9781.7497 | K5: =$B$2 + $B$3*E5 + 'Станд.норм.распр.'!E6 * $B$4 -> 9779.2575 | L5: =$B$2 + $B$3*E5 + 'Станд.норм.распр.'!F6 * $B$4 -> 9784.8769 | M5: =$B$2 + $B$3*E5 + 'Станд.норм.распр.'!G6 * $B$4 -> 9784.6237 | N5: =$B$2 + $B$3*E5 + 'Станд.норм.распр.'!H6 * $B$4 -> 9802.2117 | O5: =$B$2 + $B$3*E5 + 'Станд.норм.распр.'!I6 * $B$4 -> 9784.7951 | P5: =$B$2 + $B$3*E5 + 'Станд.норм.распр.'!J6 * $B$4 -> 9782.6191 | Q5: =$B$2 + $B$3*E5 + 'Станд.норм.распр.'!K6 * $B$4 -> 9782.3977
C6: X5 | D6: = | E6: 314 | F6: Y5 | G6: = | H6: =$B$2 + $B$3*E6 + 'Станд.норм.распр.'!B7 * $B$4 -> 3468.0361 | I6: =$B$2 + $B$3*E6 + 'Станд.норм.распр.'!C7 * $B$4 -> 3468.6232 | J6: =$B$2 + $B$3*E6 + 'Станд.норм.распр.'!D7 * $B$4 -> 3472.1674 | K6: =$B$2 + $B$3*E6 + 'Станд.норм.распр.'!E7 * $B$4 -> 3467.6677 | L6: =$B$2 + $B$3*E6 + 'Станд.норм.распр.'!F7 * $B$4 -> 3469.9163 | M6: =$B$2 + $B$3*E6 + 'Станд.норм.распр.'!G7 * $B$4 -> 3467.2069 | N6: =$B$2 + $B$3*E6 + 'Станд.норм.распр.'!H7 * $B$4 -> 3465.6011 | O6: =$B$2 + $B$3*E6 + 'Станд.норм.распр.'!I7 * $B$4 -> 3471.299 | P6: =$B$2 + $B$3*E6 + 'Станд.норм.распр.'!J7 * $B$4 -> 3468.3823 | Q6: =$B$2 + $B$3*E6 + 'Станд.норм.распр.'!K7 * $B$4 -> 3481.8136
C7: X6 | D7: = | E7: 780 | F7: Y6 | G7: = | H7: =$B$2 + $B$3*E7 + 'Станд.норм.распр.'!B8 * $B$4 -> 8586.5499 | I7: =$B$2 + $B$3*E7 + 'Станд.норм.распр.'!C8 * $B$4 -> 8577.6001 | J7: =$B$2 + $B$3*E7 + 'Станд.норм.распр.'!D8 * $B$4 -> 8599.2095 | K7: =$B$2 + $B$3*E7 + 'Станд.норм.распр.'!E8 * $B$4 -> 8585.519 | L7: =$B$2 + $B$3*E7 + 'Станд.норм.распр.'!F8 * $B$4 -> 8599.421 | M7: =$B$2 + $B$3*E7 + 'Станд.норм.распр.'!G8 * $B$4 -> 8595.7189 | N7: =$B$2 + $B$3*E7 + 'Станд.норм.распр.'!H8 * $B$4 -> 8592.1154 | O7: =$B$2 + $B$3*E7 + 'Станд.норм.распр.'!I8 * $B$4 -> 8586.8276 | P7: =$B$2 + $B$3*E7 + 'Станд.норм.распр.'!J8 * $B$4 -> 8586.4299 | Q7: =$B$2 + $B$3*E7 + 'Станд.норм.распр.'!K8 * $B$4 -> 8602.2541
C8: X7 | D8: = | E8: 993 | F8: Y7 | G8: = | H8: =$B$2 + $B$3*E8 + 'Станд.норм.распр.'!B9 * $B$4 -> 10948.658 | I8: =$B$2 + $B$3*E8 + 'Станд.норм.распр.'!C9 * $B$4 -> 10928.745 | J8: =$B$2 + $B$3*E8 + 'Станд.норм.распр.'!D9 * $B$4 -> 10945.118 | K8: =$B$2 + $B$3*E8 + 'Станд.норм.распр.'!E9 * $B$4 -> 10947.254 | L8: =$B$2 + $B$3*E8 + 'Станд.норм.распр.'!F9 * $B$4 -> 10939.274 | M8: =$B$2 + $B$3*E8 + 'Станд.норм.распр.'!G9 * $B$4 -> 10936.346 | N8: =$B$2 + $B$3*E8 + 'Станд.норм.распр.'!H9 * $B$4 -> 10942.185 | O8: =$B$2 + $B$3*E8 + 'Станд.норм.распр.'!I9 * $B$4 -> 10942.543 | P8: =$B$2 + $B$3*E8 + 'Станд.норм.распр.'!J9 * $B$4 -> 10943.691 | Q8: =$B$2 + $B$3*E8 + 'Станд.норм.распр.'!K9 * $B$4 -> 10938.776
C9: X8 | D9: = | E9: 326 | F9: Y8 | G9: = | H9: =$B$2 + $B$3*E9 + 'Станд.норм.распр.'!B10 * $B$4 -> 3602.996 | I9: =$B$2 + $B$3*E9 + 'Станд.норм.распр.'!C10 * $B$4 -> 3580.5375 | J9: =$B$2 + $B$3*E9 + 'Станд.норм.распр.'!D10 * $B$4 -> 3593.4554 | K9: =$B$2 + $B$3*E9 + 'Станд.норм.распр.'!E10 * $B$4 -> 3604.0109 | L9: =$B$2 + $B$3*E9 + 'Станд.норм.распр.'!F10 * $B$4 -> 3600.2207 | M9: =$B$2 + $B$3*E9 + 'Станд.норм.распр.'!G10 * $B$4 -> 3616.2536 | N9: =$B$2 + $B$3*E9 + 'Станд.норм.распр.'!H10 * $B$4 -> 3612.4677 | O9: =$B$2 + $B$3*E9 + 'Станд.норм.распр.'!I10 * $B$4 -> 3602.6201 | P9: =$B$2 + $B$3*E9 + 'Станд.норм.распр.'!J10 * $B$4 -> 3607.4766 | Q9: =$B$2 + $B$3*E9 + 'Станд.норм.распр.'!K10 * $B$4 -> 3589.8628
C10: X9 | D10: = | E10: 906 | F10: Y9 | G10: = | H10: =$B$2 + $B$3*E10 + 'Станд.норм.распр.'!B11 * $B$4 -> 9986.2608 | I10: =$B$2 + $B$3*E10 + 'Станд.норм.распр.'!C11 * $B$4 -> 9977.5218 | J10: =$B$2 + $B$3*E10 + 'Станд.норм.распр.'!D11 * $B$4 -> 9973.9445 | K10: =$B$2 + $B$3*E10 + 'Станд.норм.распр.'!E11 * $B$4 -> 9980.3957 | L10: =$B$2 + $B$3*E10 + 'Станд.норм.распр.'!F11 * $B$4 -> 9977.7889 | M10: =$B$2 + $B$3*E10 + 'Станд.норм.распр.'!G11 * $B$4 -> 9989.6228 | N10: =$B$2 + $B$3*E10 + 'Станд.норм.распр.'!H11 * $B$4 -> 9991.9262 | O10: =$B$2 + $B$3*E10 + 'Станд.норм.распр.'!I11 * $B$4 -> 9987.1781 | P10: =$B$2 + $B$3*E10 + 'Станд.норм.распр.'!J11 * $B$4 -> 9990.1919 | Q10: =$B$2 + $B$3*E10 + 'Станд.норм.распр.'!K11 * $B$4 -> 9983.0849
C11: X10 | D11: = | E11: 790 | F11: Y10 | G11: = | H11: =$B$2 + $B$3*E11 + 'Станд.норм.распр.'!B12 * $B$4 -> 8706.3896 | I11: =$B$2 + $B$3*E11 + 'Станд.норм.распр.'!C12 * $B$4 -> 8684.6916 | J11: =$B$2 + $B$3*E11 + 'Станд.норм.распр.'!D12 * $B$4 -> 8708.593 | K11: =$B$2 + $B$3*E11 + 'Станд.норм.распр.'!E12 * $B$4 -> 8717.515 | L11: =$B$2 + $B$3*E11 + 'Станд.норм.распр.'!F12 * $B$4 -> 8709.1453 | M11: =$B$2 + $B$3*E11 + 'Станд.норм.распр.'!G12 * $B$4 -> 8712.3489 | N11: =$B$2 + $B$3*E11 + 'Станд.норм.распр.'!H12 * $B$4 -> 8727.2951 | O11: =$B$2 + $B$3*E11 + 'Станд.норм.распр.'!I12 * $B$4 -> 8714.7527 | P11: =$B$2 + $B$3*E11 + 'Станд.норм.распр.'!J12 * $B$4 -> 8704.8581 | Q11: =$B$2 + $B$3*E11 + 'Станд.норм.распр.'!K12 * $B$4 -> 8701.3569
C12: X11 | D12: = | E12: 127 | F12: Y11 | G12: = | H12: =$B$2 + $B$3*E12 + 'Станд.норм.распр.'!B13 * $B$4 -> 1408.8803 | I12: =$B$2 + $B$3*E12 + 'Станд.норм.распр.'!C13 * $B$4 -> 1402.4824 | J12: =$B$2 + $B$3*E12 + 'Станд.норм.распр.'!D13 * $B$4 -> 1410.4168 | K12: =$B$2 + $B$3*E12 + 'Станд.норм.распр.'!E13 * $B$4 -> 1405.7489 | L12: =$B$2 + $B$3*E12 + 'Станд.норм.распр.'!F13 * $B$4 -> 1415.968 | M12: =$B$2 + $B$3*E12 + 'Станд.норм.распр.'!G13 * $B$4 -> 1403.3284 | N12: =$B$2 + $B$3*E12 + 'Станд.норм.распр.'!H13 * $B$4 -> 1412.9051 | O12: =$B$2 + $B$3*E12 + 'Станд.норм.распр.'!I13 * $B$4 -> 1432.9416 | P12: =$B$2 + $B$3*E12 + 'Станд.норм.распр.'!J13 * $B$4 -> 1407.309 | Q12: =$B$2 + $B$3*E12 + 'Станд.норм.распр.'!K13 * $B$4 -> 1409.8717
C13: X12 | D13: = | E13: 685 | F13: Y12 | G13: = | H13: =$B$2 + $B$3*E13 + 'Станд.норм.распр.'!B14 * $B$4 -> 7546.2741 | I13: =$B$2 + $B$3*E13 + 'Станд.норм.распр.'!C14 * $B$4 -> 7542.9324 | J13: =$B$2 + $B$3*E13 + 'Станд.норм.распр.'!D14 * $B$4 -> 7549.0313 | K13: =$B$2 + $B$3*E13 + 'Станд.норм.распр.'!E14 * $B$4 -> 7551.4339 | L13: =$B$2 + $B$3*E13 + 'Станд.норм.распр.'!F14 * $B$4 -> 7553.6039 | M13: =$B$2 + $B$3*E13 + 'Станд.норм.распр.'!G14 * $B$4 -> 7539.6343 | N13: =$B$2 + $B$3*E13 + 'Станд.норм.распр.'!H14 * $B$4 -> 7553.107 | O13: =$B$2 + $B$3*E13 + 'Станд.норм.распр.'!I14 * $B$4 -> 7542.6759 | P13: =$B$2 + $B$3*E13 + 'Станд.норм.распр.'!J14 * $B$4 -> 7540.8544 | Q13: =$B$2 + $B$3*E13 + 'Станд.норм.распр.'!K14 * $B$4 -> 7548.7304
C14: X13 | D14: = | E14: 320 | F14: Y13 | G14: = | H14: =$B$2 + $B$3*E14 + 'Станд.норм.распр.'!B15 * $B$4 -> 3535.3194 | I14: =$B$2 + $B$3*E14 + 'Станд.норм.распр.'!C15 * $B$4 -> 3551.5612 | J14: =$B$2 + $B$3*E14 + 'Станд.норм.распр.'!D15 * $B$4 -> 3539.2038 | K14: =$B$2 + $B$3*E14 + 'Станд.норм.распр.'!E15 * $B$4 -> 3535.9213 | L14: =$B$2 + $B$3*E14 + 'Станд.норм.распр.'!F15 * $B$4 -> 3518.7021 | M14: =$B$2 + $B$3*E14 + 'Станд.норм.распр.'!G15 * $B$4 -> 3546.2852 | N14: =$B$2 + $B$3*E14 + 'Станд.норм.распр.'!H15 * $B$4 -> 3530.6251 | O14: =$B$2 + $B$3*E14 + 'Станд.норм.распр.'!I15 * $B$4 -> 3550.2466 | P14: =$B$2 + $B$3*E14 + 'Станд.норм.распр.'!J15 * $B$4 -> 3532.3351 | Q14: =$B$2 + $B$3*E14 + 'Станд.норм.распр.'!K15 * $B$4 -> 3531.0738
C15: X14 | D15: = | E15: 658 | F15: Y14 | G15: = | H15: =$B$2 + $B$3*E15 + 'Станд.норм.распр.'!B16 * $B$4 -> 7252.0582 | I15: =$B$2 + $B$3*E15 + 'Станд.норм.распр.'!C16 * $B$4 -> 7255.0754 | J15: =$B$2 + $B$3*E15 + 'Станд.норм.распр.'!D16 * $B$4 -> 7251.8854 | K15: =$B$2 + $B$3*E15 + 'Станд.норм.распр.'!E16 * $B$4 -> 7240.8384 | L15: =$B$2 + $B$3*E15 + 'Станд.норм.распр.'!F16 * $B$4 -> 7268.0133 | M15: =$B$2 + $B$3*E15 + 'Станд.норм.распр.'!G16 * $B$4 -> 7257.5887 | N15: =$B$2 + $B$3*E15 + 'Станд.норм.распр.'!H16 * $B$4 -> 7252.586 | O15: =$B$2 + $B$3*E15 + 'Станд.норм.распр.'!I16 * $B$4 -> 7247.5149 | P15: =$B$2 + $B$3*E15 + 'Станд.норм.распр.'!J16 * $B$4 -> 7247.8808 | Q15: =$B$2 + $B$3*E15 + 'Станд.норм.распр.'!K16 * $B$4 -> 7262.7373
C16: X15 | D16: = | E16: 436 | F16: Y15 | G16: = | H16: =$B$2 + $B$3*E16 + 'Станд.норм.распр.'!B17 * $B$4 -> 4808.1027 | I16: =$B$2 + $B$3*E16 + 'Станд.норм.распр.'!C17 * $B$4 -> 4810.7537 | J16: =$B$2 + $B$3*E16 + 'Станд.норм.распр.'!D17 * $B$4 -> 4807.9821 | K16: =$B$2 + $B$3*E16 + 'Станд.норм.распр.'!E17 * $B$4 -> 4814.049 | L16: =$B$2 + $B$3*E16 + 'Станд.норм.распр.'!F17 * $B$4 -> 4800.8677 | M16: =$B$2 + $B$3*E16 + 'Станд.норм.распр.'!G17 * $B$4 -> 4810.1821 | N16: =$B$2 + $B$3*E16 + 'Станд.норм.распр.'!H17 * $B$4 -> 4810.7531 | O16: =$B$2 + $B$3*E16 + 'Станд.норм.распр.'!I17 * $B$4 -> 4809.2518 | P16: =$B$2 + $B$3*E16 + 'Станд.норм.распр.'!J17 * $B$4 -> 4808.542 | Q16: =$B$2 + $B$3*E16 + 'Станд.норм.распр.'!K17 * $B$4 -> 4808.8002
... C101: X100 | D101: = | E101: 629 | F101: Y100 | G101: = | H101: =$B$2 + $B$3*E101 + 'Станд.норм.распр.'!B102 * $B$4 -> 6947.9481 | I101: =$B$2 + $B$3*E101 + 'Станд.норм.распр.'!C102 * $B$4 -> 6930.9408 | J101: =$B$2 + $B$3*E101 + 'Станд.норм.распр.'!D102 * $B$4 -> 6916.6935 | K101: =$B$2 + $B$3*E101 + 'Станд.норм.распр.'!E102 * $B$4 -> 6946.0842 | L101: =$B$2 + $B$3*E101 + 'Станд.норм.распр.'!F102 * $B$4 -> 6922.9596 | M101: =$B$2 + $B$3*E101 + 'Станд.норм.распр.'!G102 * $B$4 -> 6924.5903 | N101: =$B$2 + $B$3*E101 + 'Станд.норм.распр.'!H102 * $B$4 -> 6941.6557 | O101: =$B$2 + $B$3*E101 + 'Станд.норм.распр.'!I102 * $B$4 -> 6934.1424 | P101: =$B$2 + $B$3*E101 + 'Станд.норм.распр.'!J102 * $B$4 -> 6917.5003 | Q101: =$B$2 + $B$3*E101 + 'Станд.норм.распр.'!K102 * $B$4 -> 6935.9044
C103: 1 ЭКС | E103: 2 ЭКС | G103: 3 ЭКС | I103: 4 ЭКС | K103: 5 ЭКС | M103: 6 ЭКС | O103: 7 ЭКС | Q103: 8 ЭКС | S103: 9 ЭКС | U103: 10 ЭКС
C104: {=LINEST(H2:H101,$E$2:$E$101,1,1)} -> 11.002208 | D104: 12.825515 | E104: {=LINEST(I2:I101,$E$2:$E$101,1,1)} -> 11.000423 | F104: 13.775068 | G104: {=LINEST(J2:J101,$E$2:$E$101,1,1)} -> 10.998469 | H104: 14.814257 | I104: {=LINEST(K2:K101,$E$2:$E$101,1,1)} -> 10.995687 | J104: 16.294747 | K104: {=LINEST(L2:L101,$E$2:$E$101,1,1)} -> 10.998763 | L104: 14.657901 | M104: {=LINEST(M2:M101,$E$2:$E$101,1,1)} -> 10.994477 | N104: 16.938115 | O104: {=LINEST(N2:N101,$E$2:$E$101,1,1)} -> 11.001086 | P104: 13.422375 | Q104: {=LINEST(O2:O101,$E$2:$E$101,1,1)} -> 10.999715 | R104: 14.15172 | S104: {=LINEST(P2:P101,$E$2:$E$101,1,1)} -> 11.002648 | T104: 12.59132 | U104: {=LINEST(Q2:Q101,$E$2:$E$101,1,1)} -> 10.999009 | V104: 14.527436
C105: 0.0028746204 | D105: 1.7218103 | E105: 0.0035244493 | F105: 2.1110381 | G105: 0.0034160845 | H105: 2.0461309 | I105: 0.0028951379 | J105: 1.7340997 | K105: 0.002842674 | L105: 1.7026754 | M105: 0.0030646512 | N105: 1.835633 | O105: 0.0034287145 | P105: 2.0536959 | Q105: 0.0034913181 | R105: 2.0911936 | S105: 0.0028241903 | T105: 1.6916042 | U105: 0.0028159199 | V105: 1.6866506
C106: 0.99999331 | D106: 7.9106915 | E106: 0.99998994 | F106: 9.6989611 | G106: 0.99999055 | H106: 9.4007512 | I106: 0.99999321 | J106: 7.9671537 | K106: 0.99999345 | L106: 7.822778 | M106: 0.99999239 | N106: 8.433639 | O106: 0.99999048 | P106: 9.4355078 | Q106: 0.99999013 | R106: 9.6077871 | S106: 0.99999354 | T106: 7.7719125 | U106: 0.99999358 | V106: 7.7491533
C107: 14648686 | D107: 98 | E107: 9741733 | F107: 98 | G107: 10365907 | H107: 98 | I107: 14424681 | J107: 98 | K107: 14970407 | L107: 98 | M107: 12870252 | N107: 98 | O107: 10294575 | P107: 98 | Q107: 9926222.5 | R107: 98 | S107: 15177720 | T107: 98 | U107: 15256906 | V107: 98
C108: 9.1670072e+08 | D108: 6132.7459 | E108: 9.1640332e+08 | F108: 9218.8449 | G108: 9.160779e+08 | H108: 8660.6641 | I108: 9.1561439e+08 | J108: 6220.6028 | K108: 9.1612686e+08 | L108: 5997.1938 | M108: 9.15413e+08 | N108: 6970.3741 | O108: 9.1651378e+08 | P108: 8724.8232 | Q108: 9.1628537e+08 | R108: 9046.3382 | S108: 9.1677408e+08 | T108: 5919.4571 | U108: 9.1616771e+08 | V108: 5884.8389
C110: Сравнение | F110: Изначальные значения
F111: a1 | G111: a0
C112: a1 | D112: a0 | E112: u | F112: 11 | G112: 14
B113: мат. ожид. | C113: =AVERAGE(C104,E104,G104,I104,K104,M104,O104,Q104,S104,U104) -> 10.999248 | D113: =AVERAGE(D104,F104,H104,J104,L104,N104,P104,R104,T104,V104) -> 14.399845 | E113: =AVERAGE(D106,F106,H106,J106,L106,N106,P106,R106,T106,V106) -> 8.5798335
B114: мин | C114: =MIN(C104,E104,G104,I104,K104,M104,O104,Q104,S104,U104) -> 10.994477 | D114: =MIN(D104,F104,H104,J104,L104,N104,P104,R104,T104,V104) -> 12.59132 | E114: =MIN(D106,F106,H106,J106,L106,N106,P106,R106,T106,V106) -> 7.7491533
B115: макс | C115: =MAX(C104,E104,G104,I104,K104,M104,O104,Q104,S104,U104) -> 11.002648 | D115: =MAX(D104,F104,H104,J104,L104,N104,P104,R104,T104,V104) -> 16.938115 | E115: =MAX(D106,F106,H106,J106,L106,N106,P106,R106,T106,V106) -> 9.6989611
B116: разброс | C116: =C115-C114 -> 0.0081705146 | D116: =D115-D114 -> 4.3467955 | E116: =E115-E114 -> 1.9498078
C118: Вывод: Оценки получились очень близкими к истинным.

Sheet 2.
A1: Ui = ui * сигма + m | C1: m=100 | D1: 100
H2: 1 экс | I2: 2 экс | J2: 3 экс | K2: 4 экс | L2: 5 экс | M2: 6 экс | N2: 7 экс | O2: 8 экс | P2: 9 экс | Q2: 10 экс
A3: а0= | B3: 14 | C3: X1 | D3: = | E3: 212 | F3: Y1 | G3: = | H3: =$B$3 + $B$4*$E3 + ('Станд.норм.распр.'!B3 * $B$5 + $D$1) -> 2445.7469 | I3: =$B$3 + $B$4*$E3 + ('Станд.норм.распр.'!C3 * $B$5 + $D$1) -> 2430.6846 | J3: =$B$3 + $B$4*$E3 + ('Станд.норм.распр.'!D3 * $B$5 + $D$1) -> 2441.1264 | K3: =$B$3 + $B$4*$E3 + ('Станд.норм.распр.'!E3 * $B$5 + $D$1) -> 2449.5931 | L3: =$B$3 + $B$4*$E3 + ('Станд.норм.распр.'!F3 * $B$5 + $D$1) -> 2437.5393 | M3: =$B$3 + $B$4*$E3 + ('Станд.норм.распр.'!G3 * $B$5 + $D$1) -> 2449.4341 | N3: =$B$3 + $B$4*$E3 + ('Станд.норм.распр.'!H3 * $B$5 + $D$1) -> 2453.9434 | O3: =$B$3 + $B$4*$E3 + ('Станд.норм.распр.'!I3 * $B$5 + $D$1) -> 2426.8996 | ... Q3: =$B$3 + $B$4*$E3 + ('Станд.норм.распр.'!K3 * $B$5 + $D$1) -> 2437.4802
A4: а1= | B4: 11 | C4: X2 | D4: = | E4: 780 | F4: Y2 | G4: = | H4: =$B$3 + $B$4*$E4 + ('Станд.норм.распр.'!B4 * $B$5 + $D$1) -> 8692.796 | I4: =$B$3 + $B$4*$E4 + ('Станд.норм.распр.'!C4 * $B$5 + $D$1) -> 8712.5313 | J4: =$B$3 + $B$4*$E4 + ('Станд.норм.распр.'!D4 * $B$5 + $D$1) -> 8712.3903 | K4: =$B$3 + $B$4*$E4 + ('Станд.норм.распр.'!E4 * $B$5 + $D$1) -> 8705.7287 | L4: =$B$3 + $B$4*$E4 + ('Станд.норм.распр.'!F4 * $B$5 + $D$1) -> 8701.0604 | M4: =$B$3 + $B$4*$E4 + ('Станд.норм.распр.'!G4 * $B$5 + $D$1) -> 8685.7596 | N4: =$B$3 + $B$4*$E4 + ('Станд.норм.распр.'!H4 * $B$5 + $D$1) -> 8686.2821 | O4: =$B$3 + $B$4*$E4 + ('Станд.норм.распр.'!I4 * $B$5 + $D$1) -> 8699.8643 | ... Q4: =$B$3 + $B$4*$E4 + ('Станд.норм.распр.'!K4 * $B$5 + $D$1) -> 8700.3321
A5: сигма= | B5: 9 | C5: X3 | D5: = | E5: 280 | F5: Y3 | G5: = | H5: =$B$3 + $B$4*$E5 + ('Станд.норм.распр.'!B5 * $B$5 + $D$1) -> 3188.2527 | I5: =$B$3 + $B$4*$E5 + ('Станд.норм.распр.'!C5 * $B$5 + $D$1) -> 3190.5325 | J5: =$B$3 + $B$4*$E5 + ('Станд.норм.распр.'!D5 * $B$5 + $D$1) -> 3202.4126 | K5: =$B$3 + $B$4*$E5 + ('Станд.норм.распр.'!E5 * $B$5 + $D$1) -> 3212.7128 | L5: =$B$3 + $B$4*$E5 + ('Станд.норм.распр.'!F5 * $B$5 + $D$1) -> 3197.3602 | M5: =$B$3 + $B$4*$E5 + ('Станд.норм.распр.'!G5 * $B$5 + $D$1) -> 3193.5361 | N5: =$B$3 + $B$4*$E5 + ('Станд.норм.распр.'!H5 * $B$5 + $D$1) -> 3205.6819 | O5: =$B$3 + $B$4*$E5 + ('Станд.норм.распр.'!I5 * $B$5 + $D$1) -> 3183.859 | ... Q5: =$B$3 + $B$4*$E5 + ('Станд.норм.распр.'!K5 * $B$5 + $D$1) -> 3187.6838
C6: X4 | D6: = | E6: 888 | F6: Y4 | G6: = | H6: =$B$3 + $B$4*$E6 + ('Станд.норм.распр.'!B6 * $B$5 + $D$1) -> 9873.9627 | I6: =$B$3 + $B$4*$E6 + ('Станд.норм.распр.'!C6 * $B$5 + $D$1) -> 9901.2947 | J6: =$B$3 + $B$4*$E6 + ('Станд.норм.распр.'!D6 * $B$5 + $D$1) -> 9881.7497 | K6: =$B$3 + $B$4*$E6 + ('Станд.норм.распр.'!E6 * $B$5 + $D$1) -> 9879.2575 | L6: =$B$3 + $B$4*$E6 + ('Станд.норм.распр.'!F6 * $B$5 + $D$1) -> 9884.8769 | M6: =$B$3 + $B$4*$E6 + ('Станд.норм.распр.'!G6 * $B$5 + $D$1) -> 9884.6237 | N6: =$B$3 + $B$4*$E6 + ('Станд.норм.распр.'!H6 * $B$5 + $D$1) -> 9902.2117 | O6: =$B$3 + $B$4*$E6 + ('Станд.норм.распр.'!I6 * $B$5 + $D$1) -> 9884.7951 | ... Q6: =$B$3 + $B$4*$E6 + ('Станд.норм.распр.'!K6 * $B$5 + $D$1) -> 9882.3977
C7: X5 | D7: = | E7: 314 | F7: Y5 | G7: = | H7: =$B$3 + $B$4*$E7 + ('Станд.норм.распр.'!B7 * $B$5 + $D$1) -> 3568.0361 | I7: =$B$3 + $B$4*$E7 + ('Станд.норм.распр.'!C7 * $B$5 + $D$1) -> 3568.6232 | J7: =$B$3 + $B$4*$E7 + ('Станд.норм.распр.'!D7 * $B$5 + $D$1) -> 3572.1674 | K7: =$B$3 + $B$4*$E7 + ('Станд.норм.распр.'!E7 * $B$5 + $D$1) -> 3567.6677 | L7: =$B$3 + $B$4*$E7 + ('Станд.норм.распр.'!F7 * $B$5 + $D$1) -> 3569.9163 | M7: =$B$3 + $B$4*$E7 + ('Станд.норм.распр.'!G7 * $B$5 + $D$1) -> 3567.2069 | N7: =$B$3 + $B$4*$E7 + ('Станд.норм.распр.'!H7 * $B$5 + $D$1) -> 3565.6011 | O7: =$B$3 + $B$4*$E7 + ('Станд.норм.распр.'!I7 * $B$5 + $D$1) -> 3571.299 | ... Q7: =$B$3 + $B$4*$E7 + ('Станд.норм.распр.'!K7 * $B$5 + $D$1) -> 3581.8136
C8: X6 | D8: = | E8: 780 | F8: Y6 | G8: = | H8: =$B$3 + $B$4*$E8 + ('Станд.норм.распр.'!B8 * $B$5 + $D$1) -> 8686.5499 | I8: =$B$3 + $B$4*$E8 + ('Станд.норм.распр.'!C8 * $B$5 + $D$1) -> 8677.6001 | J8: =$B$3 + $B$4*$E8 + ('Станд.норм.распр.'!D8 * $B$5 + $D$1) -> 8699.2095 | K8: =$B$3 + $B$4*$E8 + ('Станд.норм.распр.'!E8 * $B$5 + $D$1) -> 8685.519 | L8: =$B$3 + $B$4*$E8 + ('Станд.норм.распр.'!F8 * $B$5 + $D$1) -> 8699.421 | M8: =$B$3 + $B$4*$E8 + ('Станд.норм.распр.'!G8 * $B$5 + $D$1) -> 8695.7189 | N8: =$B$3 + $B$4*$E8 + ('Станд.норм.распр.'!H8 * $B$5 + $D$1) -> 8692.1154 | O8: =$B$3 + $B$4*$E8 + ('Станд.норм.распр.'!I8 * $B$5 + $D$1) -> 8686.8276 | ... Q8: =$B$3 + $B$4*$E8 + ('Станд.норм.распр.'!K8 * $B$5 + $D$1) -> 8702.2541
C9: X7 | D9: = | E9: 993 | F9: Y7 | G9: = | H9: =$B$3 + $B$4*$E9 + ('Станд.норм.распр.'!B9 * $B$5 + $D$1) -> 11048.658 | I9: =$B$3 + $B$4*$E9 + ('Станд.норм.распр.'!C9 * $B$5 + $D$1) -> 11028.745 | J9: =$B$3 + $B$4*$E9 + ('Станд.норм.распр.'!D9 * $B$5 + $D$1) -> 11045.118 | K9: =$B$3 + $B$4*$E9 + ('Станд.норм.распр.'!E9 * $B$5 + $D$1) -> 11047.254 | L9: =$B$3 + $B$4*$E9 + ('Станд.норм.распр.'!F9 * $B$5 + $D$1) -> 11039.274 | M9: =$B$3 + $B$4*$E9 + ('Станд.норм.распр.'!G9 * $B$5 + $D$1) -> 11036.346 | N9: =$B$3 + $B$4*$E9 + ('Станд.норм.распр.'!H9 * $B$5 + $D$1) -> 11042.185 | O9: =$B$3 + $B$4*$E9 + ('Станд.норм.распр.'!I9 * $B$5 + $D$1) -> 11042.543 | ... Q9: =$B$3 + $B$4*$E9 + ('Станд.норм.распр.'!K9 * $B$5 + $D$1) -> 11038.776
C10: X8 | D10: = | E10: 326 | F10: Y8 | G10: = | H10: =$B$3 + $B$4*$E10 + ('Станд.норм.распр.'!B10 * $B$5 + $D$1) -> 3702.996 | I10: =$B$3 + $B$4*$E10 + ('Станд.норм.распр.'!C10 * $B$5 + $D$1) -> 3680.5375 | J10: =$B$3 + $B$4*$E10 + ('Станд.норм.распр.'!D10 * $B$5 + $D$1) -> 3693.4554 | K10: =$B$3 + $B$4*$E10 + ('Станд.норм.распр.'!E10 * $B$5 + $D$1) -> 3704.0109 | L10: =$B$3 + $B$4*$E10 + ('Станд.норм.распр.'!F10 * $B$5 + $D$1) -> 3700.2207 | M10: =$B$3 + $B$4*$E10 + ('Станд.норм.распр.'!G10 * $B$5 + $D$1) -> 3716.2536 | N10: =$B$3 + $B$4*$E10 + ('Станд.норм.распр.'!H10 * $B$5 + $D$1) -> 3712.4677 | O10: =$B$3 + $B$4*$E10 + ('Станд.норм.распр.'!I10 * $B$5 + $D$1) -> 3702.6201 | ... Q10: =$B$3 + $B$4*$E10 + ('Станд.норм.распр.'!K10 * $B$5 + $D$1) -> 3689.8628
C11: X9 | D11: = | E11: 906 | F11: Y9 | G11: = | H11: =$B$3 + $B$4*$E11 + ('Станд.норм.распр.'!B11 * $B$5 + $D$1) -> 10086.261 | I11: =$B$3 + $B$4*$E11 + ('Станд.норм.распр.'!C11 * $B$5 + $D$1) -> 10077.522 | J11: =$B$3 + $B$4*$E11 + ('Станд.норм.распр.'!D11 * $B$5 + $D$1) -> 10073.944 | K11: =$B$3 + $B$4*$E11 + ('Станд.норм.распр.'!E11 * $B$5 + $D$1) -> 10080.396 | L11: =$B$3 + $B$4*$E11 + ('Станд.норм.распр.'!F11 * $B$5 + $D$1) -> 10077.789 | M11: =$B$3 + $B$4*$E11 + ('Станд.норм.распр.'!G11 * $B$5 + $D$1) -> 10089.623 | N11: =$B$3 + $B$4*$E11 + ('Станд.норм.распр.'!H11 * $B$5 + $D$1) -> 10091.926 | O11: =$B$3 + $B$4*$E11 + ('Станд.норм.распр.'!I11 * $B$5 + $D$1) -> 10087.178 | ... Q11: =$B$3 + $B$4*$E11 + ('Станд.норм.распр.'!K11 * $B$5 + $D$1) -> 10083.085
C12: X10 | D12: = | E12: 790 | F12: Y10 | G12: = | H12: =$B$3 + $B$4*$E12 + ('Станд.норм.распр.'!B12 * $B$5 + $D$1) -> 8806.3896 | I12: =$B$3 + $B$4*$E12 + ('Станд.норм.распр.'!C12 * $B$5 + $D$1) -> 8784.6916 | J12: =$B$3 + $B$4*$E12 + ('Станд.норм.распр.'!D12 * $B$5 + $D$1) -> 8808.593 | K12: =$B$3 + $B$4*$E12 + ('Станд.норм.распр.'!E12 * $B$5 + $D$1) -> 8817.515 | L12: =$B$3 + $B$4*$E12 + ('Станд.норм.распр.'!F12 * $B$5 + $D$1) -> 8809.1453 | M12: =$B$3 + $B$4*$E12 + ('Станд.норм.распр.'!G12 * $B$5 + $D$1) -> 8812.3489 | N12: =$B$3 + $B$4*$E12 + ('Станд.норм.распр.'!H12 * $B$5 + $D$1) -> 8827.2951 | O12: =$B$3 + $B$4*$E12 + ('Станд.норм.распр.'!I12 * $B$5 + $D$1) -> 8814.7527 | ... Q12: =$B$3 + $B$4*$E12 + ('Станд.норм.распр.'!K12 * $B$5 + $D$1) -> 8801.3569
C13: X11 | D13: = | E13: 127 | F13: Y11 | G13: = | H13: =$B$3 + $B$4*$E13 + ('Станд.норм.распр.'!B13 * $B$5 + $D$1) -> 1508.8803 | I13: =$B$3 + $B$4*$E13 + ('Станд.норм.распр.'!C13 * $B$5 + $D$1) -> 1502.4824 | J13: =$B$3 + $B$4*$E13 + ('Станд.норм.распр.'!D13 * $B$5 + $D$1) -> 1510.4168 | K13: =$B$3 + $B$4*$E13 + ('Станд.норм.распр.'!E13 * $B$5 + $D$1) -> 1505.7489 | L13: =$B$3 + $B$4*$E13 + ('Станд.норм.распр.'!F13 * $B$5 + $D$1) -> 1515.968 | M13: =$B$3 + $B$4*$E13 + ('Станд.норм.распр.'!G13 * $B$5 + $D$1) -> 1503.3284 | N13: =$B$3 + $B$4*$E13 + ('Станд.норм.распр.'!H13 * $B$5 + $D$1) -> 1512.9051 | O13: =$B$3 + $B$4*$E13 + ('Станд.норм.распр.'!I13 * $B$5 + $D$1) -> 1532.9416 | ... Q13: =$B$3 + $B$4*$E13 + ('Станд.норм.распр.'!K13 * $B$5 + $D$1) -> 1509.8717
C14: X12 | D14: = | E14: 685 | F14: Y12 | G14: = | H14: =$B$3 + $B$4*$E14 + ('Станд.норм.распр.'!B14 * $B$5 + $D$1) -> 7646.2741 | I14: =$B$3 + $B$4*$E14 + ('Станд.норм.распр.'!C14 * $B$5 + $D$1) -> 7642.9324 | J14: =$B$3 + $B$4*$E14 + ('Станд.норм.распр.'!D14 * $B$5 + $D$1) -> 7649.0313 | K14: =$B$3 + $B$4*$E14 + ('Станд.норм.распр.'!E14 * $B$5 + $D$1) -> 7651.4339 | L14: =$B$3 + $B$4*$E14 + ('Станд.норм.распр.'!F14 * $B$5 + $D$1) -> 7653.6039 | M14: =$B$3 + $B$4*$E14 + ('Станд.норм.распр.'!G14 * $B$5 + $D$1) -> 7639.6343 | N14: =$B$3 + $B$4*$E14 + ('Станд.норм.распр.'!H14 * $B$5 + $D$1) -> 7653.107 | O14: =$B$3 + $B$4*$E14 + ('Станд.норм.распр.'!I14 * $B$5 + $D$1) -> 7642.6759 | ... Q14: =$B$3 + $B$4*$E14 + ('Станд.норм.распр.'!K14 * $B$5 + $D$1) -> 7648.7304
C15: X13 | D15: = | E15: 320 | F15: Y13 | G15: = | H15: =$B$3 + $B$4*$E15 + ('Станд.норм.распр.'!B15 * $B$5 + $D$1) -> 3635.3194 | I15: =$B$3 + $B$4*$E15 + ('Станд.норм.распр.'!C15 * $B$5 + $D$1) -> 3651.5612 | J15: =$B$3 + $B$4*$E15 + ('Станд.норм.распр.'!D15 * $B$5 + $D$1) -> 3639.2038 | K15: =$B$3 + $B$4*$E15 + ('Станд.норм.распр.'!E15 * $B$5 + $D$1) -> 3635.9213 | L15: =$B$3 + $B$4*$E15 + ('Станд.норм.распр.'!F15 * $B$5 + $D$1) -> 3618.7021 | M15: =$B$3 + $B$4*$E15 + ('Станд.норм.распр.'!G15 * $B$5 + $D$1) -> 3646.2852 | N15: =$B$3 + $B$4*$E15 + ('Станд.норм.распр.'!H15 * $B$5 + $D$1) -> 3630.6251 | O15: =$B$3 + $B$4*$E15 + ('Станд.норм.распр.'!I15 * $B$5 + $D$1) -> 3650.2466 | ... Q15: =$B$3 + $B$4*$E15 + ('Станд.норм.распр.'!K15 * $B$5 + $D$1) -> 3631.0738
C16: X14 | D16: = | E16: 658 | F16: Y14 | G16: = | H16: =$B$3 + $B$4*$E16 + ('Станд.норм.распр.'!B16 * $B$5 + $D$1) -> 7352.0582 | I16: =$B$3 + $B$4*$E16 + ('Станд.норм.распр.'!C16 * $B$5 + $D$1) -> 7355.0754 | J16: =$B$3 + $B$4*$E16 + ('Станд.норм.распр.'!D16 * $B$5 + $D$1) -> 7351.8854 | K16: =$B$3 + $B$4*$E16 + ('Станд.норм.распр.'!E16 * $B$5 + $D$1) -> 7340.8384 | L16: =$B$3 + $B$4*$E16 + ('Станд.норм.распр.'!F16 * $B$5 + $D$1) -> 7368.0133 | M16: =$B$3 + $B$4*$E16 + ('Станд.норм.распр.'!G16 * $B$5 + $D$1) -> 7357.5887 | N16: =$B$3 + $B$4*$E16 + ('Станд.норм.распр.'!H16 * $B$5 + $D$1) -> 7352.586 | O16: =$B$3 + $B$4*$E16 + ('Станд.норм.распр.'!I16 * $B$5 + $D$1) -> 7347.5149 | ... Q16: =$B$3 + $B$4*$E16 + ('Станд.норм.распр.'!K16 * $B$5 + $D$1) -> 7362.7373
C17: X15 | D17: = | E17: 436 | F17: Y15 | G17: = | H17: =$B$3 + $B$4*$E17 + ('Станд.норм.распр.'!B17 * $B$5 + $D$1) -> 4908.1027 | I17: =$B$3 + $B$4*$E17 + ('Станд.норм.распр.'!C17 * $B$5 + $D$1) -> 4910.7537 | J17: =$B$3 + $B$4*$E17 + ('Станд.норм.распр.'!D17 * $B$5 + $D$1) -> 4907.9821 | K17: =$B$3 + $B$4*$E17 + ('Станд.норм.распр.'!E17 * $B$5 + $D$1) -> 4914.049 | L17: =$B$3 + $B$4*$E17 + ('Станд.норм.распр.'!F17 * $B$5 + $D$1) -> 4900.8677 | M17: =$B$3 + $B$4*$E17 + ('Станд.норм.распр.'!G17 * $B$5 + $D$1) -> 4910.1821 | N17: =$B$3 + $B$4*$E17 + ('Станд.норм.распр.'!H17 * $B$5 + $D$1) -> 4910.7531 | O17: =$B$3 + $B$4*$E17 + ('Станд.норм.распр.'!I17 * $B$5 + $D$1) -> 4909.2518 | ... Q17: =$B$3 + $B$4*$E17 + ('Станд.норм.распр.'!K17 * $B$5 + $D$1) -> 4908.8002
... C102: X100 | D102: = | E102: 629 | F102: Y100 | G102: = | H102: =$B$3 + $B$4*$E102 + ('Станд.норм.распр.'!B102 * $B$5 + $D$1) -> 7047.9481 | I102: =$B$3 + $B$4*$E102 + ('Станд.норм.распр.'!C102 * $B$5 + $D$1) -> 7030.9408 | J102: =$B$3 + $B$4*$E102 + ('Станд.норм.распр.'!D102 * $B$5 + $D$1) -> 7016.6935 | K102: =$B$3 + $B$4*$E102 + ('Станд.норм.распр.'!E102 * $B$5 + $D$1) -> 7046.0842 | L102: =$B$3 + $B$4*$E102 + ('Станд.норм.распр.'!F102 * $B$5 + $D$1) -> 7022.9596 | M102: =$B$3 + $B$4*$E102 + ('Станд.норм.распр.'!G102 * $B$5 + $D$1) -> 7024.5903 | N102: =$B$3 + $B$4*$E102 + ('Станд.норм.распр.'!H102 * $B$5 + $D$1) -> 7041.6557 | O102: =$B$3 + $B$4*$E102 + ('Станд.норм.распр.'!I102 * $B$5 + $D$1) -> 7034.1424 | ... Q102: =$B$3 + $B$4*$E102 + ('Станд.норм.распр.'!K102 * $B$5 + $D$1) -> 7035.9044
C104: 1 ЭКС | E104: 2 ЭКС | G104: 3 ЭКС | I104: 4 ЭКС | K104: 5 ЭКС | M104: 6 ЭКС | O104: 7 ЭКС | Q104: 8 ЭКС | S104: 9 ЭКС | U104: 10 ЭКС
C105: {=LINEST(H3:H102,$E$3:$E$102,1,1)} -> 11.002208 | D105: 112.82552 | E105: {=LINEST(I3:I102,$E$3:$E$102,1,1)} -> 11.000423 | F105: 113.77507 | G105: {=LINEST(J3:J102,$E$3:$E$102,1,1)} -> 10.998469 | H105: 114.81426 | I105: {=LINEST(K3:K102,$E$3:$E$102,1,1)} -> 10.995687 | J105: 116.29475 | K105: {=LINEST(L3:L102,$E$3:$E$102,1,1)} -> 10.998763 | L105: 114.6579 | M105: {=LINEST(M3:M102,$E$3:$E$102,1,1)} -> 10.994477 | N105: 116.93812 | O105: {=LINEST(N3:N102,$E$3:$E$102,1,1)} -> 11.001086 | P105: 113.42238 | Q105: {=LINEST(O3:O102,$E$3:$E$102,1,1)} -> 10.999715 | R105: 114.15172 | S105: {=LINEST(P3:P102,$E$3:$E$102,1,1)} -> 11.002648 | T105: 112.59132 | U105: {=LINEST(Q3:Q102,$E$3:$E$102,1,1)} -> 10.999009 | V105: 114.52744
C106: 0.0028746204 | D106: 1.7218103 | E106: 0.0035244493 | F106: 2.1110381 | G106: 0.0034160845 | H106: 2.0461309 | I106: 0.0028951379 | J106: 1.7340997 | K106: 0.002842674 | L106: 1.7026754 | M106: 0.0030646512 | N106: 1.835633 | O106: 0.0034287145 | P106: 2.0536959 | Q106: 0.0034913181 | R106: 2.0911936 | S106: 0.0028241903 | T106: 1.6916042 | U106: 0.0028159199 | V106: 1.6866506
C107: 0.99999331 | D107: 7.9106915 | E107: 0.99998994 | F107: 9.6989611 | G107: 0.99999055 | H107: 9.4007512 | I107: 0.99999321 | J107: 7.9671537 | K107: 0.99999345 | L107: 7.822778 | M107: 0.99999239 | N107: 8.433639 | O107: 0.99999048 | P107: 9.4355078 | Q107: 0.99999013 | R107: 9.6077871 | S107: 0.99999354 | T107: 7.7719125 | U107: 0.99999358 | V107: 7.7491533
C108: 14648686 | D108: 98 | E108: 9741733 | F108: 98 | G108: 10365907 | H108: 98 | I108: 14424681 | J108: 98 | K108: 14970407 | L108: 98 | M108: 12870252 | N108: 98 | O108: 10294575 | P108: 98 | Q108: 9926222.5 | R108: 98 | S108: 15177720 | T108: 98 | U108: 15256906 | V108: 98
C109: 9.1670072e+08 | D109: 6132.7459 | E109: 9.1640332e+08 | F109: 9218.8449 | G109: 9.160779e+08 | H109: 8660.6641 | I109: 9.1561439e+08 | J109: 6220.6028 | K109: 9.1612686e+08 | L109: 5997.1938 | M109: 9.15413e+08 | N109: 6970.3741 | O109: 9.1651378e+08 | P109: 8724.8232 | Q109: 9.1628537e+08 | R109: 9046.3382 | S109: 9.1677408e+08 | T109: 5919.4571 | U109: 9.1616771e+08 | V109: 5884.8389
C111: Сравнение | F111: Изначальные значения | I111: При соблюдении всех условий
F112: a1 | G112: a0
C113: a1 | D113: a0 | E113: u | F113: 11 | G113: 14 | J113: a1 | K113: a0 | L113: u
B114: мат. ожид. | C114: =AVERAGE(C105,E105,G105,I105,K105,M105,O105,Q105,S105,U105) -> 10.999248 | D114: =AVERAGE(D105,F105,H105,J105,L105,N105,P105,R105,T105,V105) -> 114.39985 | E114: =AVERAGE(D107,F107,H107,J107,L107,N107,P107,R107,T107,V107) -> 8.5798335 | I114: мат. ожид. | J114: 10.999248 | K114: 14.399845 | L114: 8.5798335
B115: мин | C115: =MIN(C105,E105,G105,I105,K105,M105,O105,Q105,S105,U105) -> 10.994477 | D115: =MIN(D105,F105,H105,J105,L105,N105,P105,R105,T105,V105) -> 112.59132 | E115: =MIN(D107,F107,H107,J107,L107,N107,P107,R107,T107,V107) -> 7.7491533 | I115: мин | J115: 10.994477 | K115: 12.59132 | L115: 7.7491533
B116: макс | C116: =MAX(C105,E105,G105,I105,K105,M105,O105,Q105,S105,U105) -> 11.002648 | D116: =MAX(D105,F105,H105,J105,L105,N105,P105,R105,T105,V105) -> 116.93812 | E116: =MAX(D107,F107,H107,J107,L107,N107,P107,R107,T107,V107) -> 9.6989611 | I116: макс | J116: 11.002648 | K116: 16.938115 | L116: 9.6989611
B117: разброс | C117: =C116-C115 -> 0.0081705146 | D117: =D116-D115 -> 4.3467955 | E117: =E116-E115 -> 1.9498078 | I117: разброс | J117: 0.0081705146 | K117: 4.3467955 | L117: 1.9498078
C120: Вывод: Среднее остатков сдвинулось на 100 - этот сдвиг целиком ушёл в a0. Наклон не пострадал. Оценка a₀ стала сильно смещённой

Sheet 3.
A1: Ui = ui * сигма * i | C1: i = 1-100
H2: 1 экс | I2: 2 экс | J2: 3 экс | K2: 4 экс | L2: 5 экс | M2: 6 экс | N2: 7 экс | O2: 8 экс | P2: 9 экс | Q2: 10 экс
A3: а0= | B3: 14 | C3: X1 | D3: = | E3: 212 | F3: Y1 | G3: = | H3: =$B$3+$B$4*$E3+('Станд.норм.распр.'!B3*$B$5*$S3) -> 2345.7469 | I3: =$B$3+$B$4*$E3+('Станд.норм.распр.'!C3*$B$5*$S3) -> 2330.6846 | J3: =$B$3+$B$4*$E3+('Станд.норм.распр.'!D3*$B$5*$S3) -> 2341.1264 | K3: =$B$3+$B$4*$E3+('Станд.норм.распр.'!E3*$B$5*$S3) -> 2349.5931 | L3: =$B$3+$B$4*$E3+('Станд.норм.распр.'!F3*$B$5*$S3) -> 2337.5393 | M3: =$B$3+$B$4*$E3+('Станд.норм.распр.'!G3*$B$5*$S3) -> 2349.4341 | N3: =$B$3+$B$4*$E3+('Станд.норм.распр.'!H3*$B$5*$S3) -> 2353.9434 | O3: =$B$3+$B$4*$E3+('Станд.норм.распр.'!I3*$B$5*$S3) -> 2326.8996 | ... Q3: =$B$3+$B$4*$E3+('Станд.норм.распр.'!K3*$B$5*$S3) -> 2337.4802 | S3: 1
A4: а1= | B4: 11 | C4: X2 | D4: = | E4: 780 | F4: Y2 | G4: = | H4: =$B$3+$B$4*$E4+('Станд.норм.распр.'!B4*$B$5*$S4) -> 8591.5921 | I4: =$B$3+$B$4*$E4+('Станд.норм.распр.'!C4*$B$5*$S4) -> 8631.0626 | J4: =$B$3+$B$4*$E4+('Станд.норм.распр.'!D4*$B$5*$S4) -> 8630.7805 | K4: =$B$3+$B$4*$E4+('Станд.норм.распр.'!E4*$B$5*$S4) -> 8617.4574 | L4: =$B$3+$B$4*$E4+('Станд.норм.распр.'!F4*$B$5*$S4) -> 8608.1208 | M4: =$B$3+$B$4*$E4+('Станд.норм.распр.'!G4*$B$5*$S4) -> 8577.5191 | N4: =$B$3+$B$4*$E4+('Станд.норм.распр.'!H4*$B$5*$S4) -> 8578.5642 | O4: =$B$3+$B$4*$E4+('Станд.норм.распр.'!I4*$B$5*$S4) -> 8605.7286 | ... Q4: =$B$3+$B$4*$E4+('Станд.норм.распр.'!K4*$B$5*$S4) -> 8606.6642 | S4: 2
A5: сигма= | B5: 9 | C5: X3 | D5: = | E5: 280 | F5: Y3 | G5: = | H5: =$B$3+$B$4*$E5+('Станд.норм.распр.'!B5*$B$5*$S5) -> 3076.758 | I5: =$B$3+$B$4*$E5+('Станд.норм.распр.'!C5*$B$5*$S5) -> 3083.5976 | J5: =$B$3+$B$4*$E5+('Станд.норм.распр.'!D5*$B$5*$S5) -> 3119.2378 | K5: =$B$3+$B$4*$E5+('Станд.норм.распр.'!E5*$B$5*$S5) -> 3150.1383 | L5: =$B$3+$B$4*$E5+('Станд.норм.распр.'!F5*$B$5*$S5) -> 3104.0806 | M5: =$B$3+$B$4*$E5+('Станд.норм.распр.'!G5*$B$5*$S5) -> 3092.6083 | N5: =$B$3+$B$4*$E5+('Станд.норм.распр.'!H5*$B$5*$S5) -> 3129.0458 | O5: =$B$3+$B$4*$E5+('Станд.норм.распр.'!I5*$B$5*$S5) -> 3063.5769 | ... Q5: =$B$3+$B$4*$E5+('Станд.норм.распр.'!K5*$B$5*$S5) -> 3075.0514 | S5: 3
C6: X4 | D6: = | E6: 888 | F6: Y4 | G6: = | H6: =$B$3+$B$4*$E6+('Станд.норм.распр.'!B6*$B$5*$S6) -> 9749.8507 | I6: =$B$3+$B$4*$E6+('Станд.норм.распр.'!C6*$B$5*$S6) -> 9859.179 | J6: =$B$3+$B$4*$E6+('Станд.норм.распр.'!D6*$B$5*$S6) -> 9780.9988 | K6: =$B$3+$B$4*$E6+('Станд.норм.распр.'!E6*$B$5*$S6) -> 9771.0302 | L6: =$B$3+$B$4*$E6+('Станд.норм.распр.'!F6*$B$5*$S6) -> 9793.5076 | M6: =$B$3+$B$4*$E6+('Станд.норм.распр.'!G6*$B$5*$S6) -> 9792.4947 | N6: =$B$3+$B$4*$E6+('Станд.норм.распр.'!H6*$B$5*$S6) -> 9862.8467 | O6: =$B$3+$B$4*$E6+('Станд.норм.распр.'!I6*$B$5*$S6) -> 9793.1806 | ... Q6: =$B$3+$B$4*$E6+('Станд.норм.распр.'!K6*$B$5*$S6) -> 9783.5909 | S6: 4
C7: X5 | D7: = | E7: 314 | F7: Y5 | G7: = | H7: =$B$3+$B$4*$E7+('Станд.норм.распр.'!B7*$B$5*$S7) -> 3468.1807 | I7: =$B$3+$B$4*$E7+('Станд.норм.распр.'!C7*$B$5*$S7) -> 3471.1162 | J7: =$B$3+$B$4*$E7+('Станд.норм.распр.'!D7*$B$5*$S7) -> 3488.8371 | K7: =$B$3+$B$4*$E7+('Станд.норм.распр.'!E7*$B$5*$S7) -> 3466.3387 | L7: =$B$3+$B$4*$E7+('Станд.норм.распр.'!F7*$B$5*$S7) -> 3477.5816 | M7: =$B$3+$B$4*$E7+('Станд.норм.распр.'!G7*$B$5*$S7) -> 3464.0344 | N7: =$B$3+$B$4*$E7+('Станд.норм.распр.'!H7*$B$5*$S7) -> 3456.0054 | O7: =$B$3+$B$4*$E7+('Станд.норм.распр.'!I7*$B$5*$S7) -> 3484.495 | ... Q7: =$B$3+$B$4*$E7+('Станд.норм.распр.'!K7*$B$5*$S7) -> 3537.0682 | S7: 5
C8: X6 | D8: = | E8: 780 | F8: Y6 | G8: = | H8: =$B$3+$B$4*$E8+('Станд.норм.распр.'!B8*$B$5*$S8) -> 8549.2992 | I8: =$B$3+$B$4*$E8+('Станд.норм.распр.'!C8*$B$5*$S8) -> 8495.6005 | J8: =$B$3+$B$4*$E8+('Станд.норм.распр.'!D8*$B$5*$S8) -> 8625.2571 | K8: =$B$3+$B$4*$E8+('Станд.норм.распр.'!E8*$B$5*$S8) -> 8543.1137 | L8: =$B$3+$B$4*$E8+('Станд.норм.распр.'!F8*$B$5*$S8) -> 8626.526 | M8: =$B$3+$B$4*$E8+('Станд.норм.распр.'!G8*$B$5*$S8) -> 8604.3132 | N8: =$B$3+$B$4*$E8+('Станд.норм.распр.'!H8*$B$5*$S8) -> 8582.6921 | O8: =$B$3+$B$4*$E8+('Станд.норм.распр.'!I8*$B$5*$S8) -> 8550.9656 | ... Q8: =$B$3+$B$4*$E8+('Станд.норм.распр.'!K8*$B$5*$S8) -> 8643.5244 | S8: 6
C9: X7 | D9: = | E9: 993 | F9: Y7 | G9: = | H9: =$B$3+$B$4*$E9+('Станд.норм.распр.'!B9*$B$5*$S9) -> 11018.608 | I9: =$B$3+$B$4*$E9+('Станд.норм.распр.'!C9*$B$5*$S9) -> 10879.214 | J9: =$B$3+$B$4*$E9+('Станд.норм.распр.'!D9*$B$5*$S9) -> 10993.824 | K9: =$B$3+$B$4*$E9+('Станд.норм.распр.'!E9*$B$5*$S9) -> 11008.775 | L9: =$B$3+$B$4*$E9+('Станд.норм.распр.'!F9*$B$5*$S9) -> 10952.92 | M9: =$B$3+$B$4*$E9+('Станд.норм.распр.'!G9*$B$5*$S9) -> 10932.42 | N9: =$B$3+$B$4*$E9+('Станд.норм.распр.'!H9*$B$5*$S9) -> 10973.296 | O9: =$B$3+$B$4*$E9+('Станд.норм.распр.'!I9*$B$5*$S9) -> 10975.8 | ... Q9: =$B$3+$B$4*$E9+('Станд.норм.распр.'!K9*$B$5*$S9) -> 10949.435 | S9: 7
C10: X8 | D10: = | E10: 326 | F10: Y8 | G10: = | H10: =$B$3+$B$4*$E10+('Станд.норм.распр.'!B10*$B$5*$S10) -> 3623.9679 | I10: =$B$3+$B$4*$E10+('Станд.норм.распр.'!C10*$B$5*$S10) -> 3444.2996 | J10: =$B$3+$B$4*$E10+('Станд.норм.распр.'!D10*$B$5*$S10) -> 3547.6431 | K10: =$B$3+$B$4*$E10+('Станд.норм.распр.'!E10*$B$5*$S10) -> 3632.0875 | L10: =$B$3+$B$4*$E10+('Станд.норм.распр.'!F10*$B$5*$S10) -> 3601.7654 | M10: =$B$3+$B$4*$E10+('Станд.норм.распр.'!G10*$B$5*$S10) -> 3730.0289 | N10: =$B$3+$B$4*$E10+('Станд.норм.распр.'!H10*$B$5*$S10) -> 3699.7419 | O10: =$B$3+$B$4*$E10+('Станд.норм.распр.'!I10*$B$5*$S10) -> 3620.9607 | ... Q10: =$B$3+$B$4*$E10+('Станд.норм.распр.'!K10*$B$5*$S10) -> 3518.9028 | S10: 8
C11: X9 | D11: = | E11: 906 | F11: Y9 | G11: = | H11: =$B$3+$B$4*$E11+('Станд.норм.распр.'!B11*$B$5*$S11) -> 10036.348 | I11: =$B$3+$B$4*$E11+('Станд.норм.распр.'!C11*$B$5*$S11) -> 9957.6963 | J11: =$B$3+$B$4*$E11+('Станд.норм.распр.'!D11*$B$5*$S11) -> 9925.5005 | K11: =$B$3+$B$4*$E11+('Станд.норм.распр.'!E11*$B$5*$S11) -> 9983.561 | L11: =$B$3+$B$4*$E11+('Станд.норм.распр.'!F11*$B$5*$S11) -> 9960.1002 | M11: =$B$3+$B$4*$E11+('Станд.норм.распр.'!G11*$B$5*$S11) -> 10066.605 | N11: =$B$3+$B$4*$E11+('Станд.норм.распр.'!H11*$B$5*$S11) -> 10087.336 | O11: =$B$3+$B$4*$E11+('Станд.норм.распр.'!I11*$B$5*$S11) -> 10044.603 | ... Q11: =$B$3+$B$4*$E11+('Станд.норм.распр.'!K11*$B$5*$S11) -> 10007.764 | S11: 9
C12: X10 | D12: = | E12: 790 | F12: Y10 | G12: = | H12: =$B$3+$B$4*$E12+('Станд.норм.распр.'!B12*$B$5*$S12) -> 8727.8964 | I12: =$B$3+$B$4*$E12+('Станд.норм.распр.'!C12*$B$5*$S12) -> 8510.9158 | J12: =$B$3+$B$4*$E12+('Станд.норм.распр.'!D12*$B$5*$S12) -> 8749.9296 | K12: =$B$3+$B$4*$E12+('Станд.норм.распр.'!E12*$B$5*$S12) -> 8839.15 | L12: =$B$3+$B$4*$E12+('Станд.норм.распр.'!F12*$B$5*$S12) -> 8755.4533 | M12: =$B$3+$B$4*$E12+('Станд.норм.распр.'!G12*$B$5*$S12) -> 8787.4887 | N12: =$B$3+$B$4*$E12+('Станд.норм.распр.'!H12*$B$5*$S12) -> 8936.9514 | O12: =$B$3+$B$4*$E12+('Станд.норм.распр.'!I12*$B$5*$S12) -> 8811.5274 | ... Q12: =$B$3+$B$4*$E12+('Станд.норм.распр.'!K12*$B$5*$S12) -> 8677.5692 | S12: 10
C13: X11 | D13: = | E13: 127 | F13: Y11 | G13: = | H13: =$B$3+$B$4*$E13+('Станд.норм.распр.'!B13*$B$5*$S13) -> 1387.6837 | I13: =$B$3+$B$4*$E13+('Станд.норм.распр.'!C13*$B$5*$S13) -> 1317.3062 | J13: =$B$3+$B$4*$E13+('Станд.норм.распр.'!D13*$B$5*$S13) -> 1404.5847 | K13: =$B$3+$B$4*$E13+('Станд.норм.распр.'!E13*$B$5*$S13) -> 1353.238 | L13: =$B$3+$B$4*$E13+('Станд.норм.распр.'!F13*$B$5*$S13) -> 1465.6477 | M13: =$B$3+$B$4*$E13+('Станд.норм.распр.'!G13*$B$5*$S13) -> 1326.6127 | N13: =$B$3+$B$4*$E13+('Станд.норм.распр.'!H13*$B$5*$S13) -> 1431.9557 | O13: =$B$3+$B$4*$E13+('Станд.норм.распр.'!I13*$B$5*$S13) -> 1652.3576 | ... Q13: =$B$3+$B$4*$E13+('Станд.норм.распр.'!K13*$B$5*$S13) -> 1398.5889 | S13: 11
C14: X12 | D14: = | E14: 685 | F14: Y12 | G14: = | H14: =$B$3+$B$4*$E14+('Станд.норм.распр.'!B14*$B$5*$S14) -> 7516.2897 | I14: =$B$3+$B$4*$E14+('Станд.норм.распр.'!C14*$B$5*$S14) -> 7476.1889 | J14: =$B$3+$B$4*$E14+('Станд.норм.распр.'!D14*$B$5*$S14) -> 7549.376 | K14: =$B$3+$B$4*$E14+('Станд.норм.распр.'!E14*$B$5*$S14) -> 7578.2066 | L14: =$B$3+$B$4*$E14+('Станд.норм.распр.'!F14*$B$5*$S14) -> 7604.2474 | M14: =$B$3+$B$4*$E14+('Станд.норм.распр.'!G14*$B$5*$S14) -> 7436.6112 | N14: =$B$3+$B$4*$E14+('Станд.норм.распр.'!H14*$B$5*$S14) -> 7598.2837 | O14: =$B$3+$B$4*$E14+('Станд.норм.распр.'!I14*$B$5*$S14) -> 7473.1103 | ... Q14: =$B$3+$B$4*$E14+('Станд.норм.распр.'!K14*$B$5*$S14) -> 7545.7649 | S14: 12
C15: X13 | D15: = | E15: 320 | F15: Y13 | G15: = | H15: =$B$3+$B$4*$E15+('Станд.норм.распр.'!B15*$B$5*$S15) -> 3551.1518 | I15: =$B$3+$B$4*$E15+('Станд.норм.распр.'!C15*$B$5*$S15) -> 3762.296 | J15: =$B$3+$B$4*$E15+('Станд.норм.распр.'!D15*$B$5*$S15) -> 3601.6497 | K15: =$B$3+$B$4*$E15+('Станд.норм.распр.'!E15*$B$5*$S15) -> 3558.9764 | L15: =$B$3+$B$4*$E15+('Станд.норм.распр.'!F15*$B$5*$S15) -> 3335.1276 | M15: =$B$3+$B$4*$E15+('Станд.норм.распр.'!G15*$B$5*$S15) -> 3693.7073 | N15: =$B$3+$B$4*$E15+('Станд.норм.распр.'!H15*$B$5*$S15) -> 3490.1259 | O15: =$B$3+$B$4*$E15+('Станд.норм.распр.'!I15*$B$5*$S15) -> 3745.2054 | ... Q15: =$B$3+$B$4*$E15+('Станд.норм.распр.'!K15*$B$5*$S15) -> 3495.9592 | S15: 13
C16: X14 | D16: = | E16: 658 | F16: Y14 | G16: = | H16: =$B$3+$B$4*$E16+('Станд.норм.распр.'!B16*$B$5*$S16) -> 7252.8145 | I16: =$B$3+$B$4*$E16+('Станд.норм.распр.'!C16*$B$5*$S16) -> 7295.056 | J16: =$B$3+$B$4*$E16+('Станд.норм.распр.'!D16*$B$5*$S16) -> 7250.3951 | K16: =$B$3+$B$4*$E16+('Станд.норм.распр.'!E16*$B$5*$S16) -> 7095.7382 | L16: =$B$3+$B$4*$E16+('Станд.норм.распр.'!F16*$B$5*$S16) -> 7476.186 | M16: =$B$3+$B$4*$E16+('Станд.норм.распр.'!G16*$B$5*$S16) -> 7330.2415 | N16: =$B$3+$B$4*$E16+('Станд.норм.распр.'!H16*$B$5*$S16) -> 7260.2037 | O16: =$B$3+$B$4*$E16+('Станд.норм.распр.'!I16*$B$5*$S16) -> 7189.2091 | ... Q16: =$B$3+$B$4*$E16+('Станд.норм.распр.'!K16*$B$5*$S16) -> 7402.3223 | S16: 14
C17: X15 | D17: = | E17: 436 | F17: Y15 | G17: = | H17: =$B$3+$B$4*$E17+('Станд.норм.распр.'!B17*$B$5*$S17) -> 4781.5403 | I17: =$B$3+$B$4*$E17+('Станд.норм.распр.'!C17*$B$5*$S17) -> 4821.3061 | J17: =$B$3+$B$4*$E17+('Станд.норм.распр.'!D17*$B$5*$S17) -> 4779.732 | K17: =$B$3+$B$4*$E17+('Станд.норм.распр.'!E17*$B$5*$S17) -> 4870.7349 | L17: =$B$3+$B$4*$E17+('Станд.норм.распр.'!F17*$B$5*$S17) -> 4673.016 | M17: =$B$3+$B$4*$E17+('Станд.норм.распр.'!G17*$B$5*$S17) -> 4812.7317 | N17: =$B$3+$B$4*$E17+('Станд.норм.распр.'!H17*$B$5*$S17) -> 4821.2958 | O17: =$B$3+$B$4*$E17+('Станд.норм.распр.'!I17*$B$5*$S17) -> 4798.7768 | ... Q17: =$B$3+$B$4*$E17+('Станд.норм.распр.'!K17*$B$5*$S17) -> 4792.003 | S17: 15
... C102: X100 | D102: = | E102: 629 | F102: Y100 | G102: = | H102: =$B$3+$B$4*$E102+('Станд.норм.распр.'!B102*$B$5*$S102) -> 8427.81 | I102: =$B$3+$B$4*$E102+('Станд.норм.распр.'!C102*$B$5*$S102) -> 6727.0776 | J102: =$B$3+$B$4*$E102+('Станд.норм.распр.'!D102*$B$5*$S102) -> 5302.3479 | K102: =$B$3+$B$4*$E102+('Станд.норм.распр.'!E102*$B$5*$S102) -> 8241.4185 | L102: =$B$3+$B$4*$E102+('Станд.норм.распр.'!F102*$B$5*$S102) -> 5928.9619 | M102: =$B$3+$B$4*$E102+('Станд.норм.распр.'!G102*$B$5*$S102) -> 6092.0296 | N102: =$B$3+$B$4*$E102+('Станд.норм.распр.'!H102*$B$5*$S102) -> 7798.5728 | O102: =$B$3+$B$4*$E102+('Станд.норм.распр.'!I102*$B$5*$S102) -> 7047.2379 | ... Q102: =$B$3+$B$4*$E102+('Станд.норм.распр.'!K102*$B$5*$S102) -> 7223.4424 | S102: 100
C104: 1 ЭКС | E104: 2 ЭКС | G104: 3 ЭКС | I104: 4 ЭКС | K104: 5 ЭКС | M104: 6 ЭКС | O104: 7 ЭКС | Q104: 8 ЭКС | S104: 9 ЭКС | U104: 10 ЭКС
C105: {=LINEST(H3:H102,$E$3:$E$102,1,1)} -> 11.155665 | D105: -59.817962 | E105: {=LINEST(I3:I102,$E$3:$E$102,1,1)} -> 10.960857 | F105: 46.210494 | G105: {=LINEST(J3:J102,$E$3:$E$102,1,1)} -> 10.872993 | H105: 11.432917 | I105: {=LINEST(K3:K102,$E$3:$E$102,1,1)} -> 10.721929 | J105: 130.03951 | K105: {=LINEST(L3:L102,$E$3:$E$102,1,1)} -> 10.874791 | L105: 43.302992 | M105: {=LINEST(M3:M102,$E$3:$E$102,1,1)} -> 10.711721 | N105: 138.61802 | O105: {=LINEST(N3:N102,$E$3:$E$102,1,1)} -> 11.036993 | P105: -42.465167 | Q105: {=LINEST(O3:O102,$E$3:$E$102,1,1)} -> 10.840783 | R105: 103.14779 | S105: {=LINEST(P3:P102,$E$3:$E$102,1,1)} -> 11.198268 | T105: -78.926404 | U105: {=LINEST(Q3:Q102,$E$3:$E$102,1,1)} -> 10.829284 | V105: 99.350713
C106: 0.1948603 | D106: 116.7154 | E106: 0.20749406 | F106: 124.28264 | G106: 0.20817782 | H106: 124.69219 | I106: 0.16935479 | J106: 101.43838 | K106: 0.15483126 | L106: 92.739222 | M106: 0.19559865 | N106: 117.15765 | O106: 0.17576589 | P106: 105.27843 | Q106: 0.20001096 | R106: 119.80049 | S106: 0.19333611 | T106: 115.80246 | U106: 0.14673108 | V106: 87.887464
C107: 0.97096736 | D107: 536.23767 | E107: 0.96607203 | F107: 571.0046 | G107: 0.96532085 | H107: 572.88626 | I107: 0.97613373 | J107: 466.04884 | K107: 0.98052136 | L107: 426.08141 | M107: 0.9683572 | N107: 538.26953 | O107: 0.97574888 | P107: 483.69159 | Q107: 0.96771794 | R107: 550.41181 | S107: 0.97161782 | T107: 532.04324 | U107: 0.98232634 | V107: 403.79048
C108: 3277.5115 | D108: 98 | E108: 2790.4723 | F108: 98 | G108: 2727.9052 | H108: 98 | I108: 4008.2143 | J108: 98 | K108: 4933.1527 | L108: 98 | M108: 2999.0713 | N108: 98 | O108: 3943.0509 | P108: 98 | Q108: 2937.7422 | R108: 98 | S108: 3354.8707 | T108: 98 | U108: 5446.9735 | V108: 98
C109: 9.4245117e+08 | D109: 28179982 | E109: 9.0982305e+08 | F109: 31952533 | G109: 8.9529486e+08 | H109: 32163469 | I109: 8.7059024e+08 | J109: 21285749 | K109: 8.9559104e+08 | L109: 17791446 | M109: 8.6893319e+08 | N109: 28393941 | O109: 9.2250655e+08 | P109: 22927841 | Q109: 8.8999827e+08 | R109: 29689410 | S109: 9.4966328e+08 | T109: 27740861 | U109: 8.8811131e+08 | V109: 15978581
C111: Сравнение | F111: Изначальные значения | I111: При соблюдении всех условий
C113: a1 | D113: a0 | E113: u | F113: a1 | G113: a0 | J113: a1 | K113: a0
B114: мат. ожид. | C114: =AVERAGE(C105,E105,G105,I105,K105,M105,O105,Q105,S105,U105) -> 10.920328 | D114: =AVERAGE(D105,F105,H105,J105,L105,N105,P105,R105,T105,V105) -> 39.089291 | E114: =AVERAGE(D107,F107,H107,J107,L107,N107,P107,R107,T107,V107) -> 508.04654 | F114: 11 | G114: 14 | I114: мат. ожид. | J114: 10.999248 | K114: 14.399845
B115: мин | C115: =MIN(C105,E105,G105,I105,K105,M105,O105,Q105,S105,U105) -> 10.711721 | D115: =MIN(D105,F105,H105,J105,L105,N105,P105,R105,T105,V105) -> -78.926404 | E115: =MIN(D107,F107,H107,J107,L107,N107,P107,R107,T107,V107) -> 403.79048 | I115: мин | J115: 10.994477 | K115: 12.59132
B116: макс | C116: =MAX(C105,E105,G105,I105,K105,M105,O105,Q105,S105,U105) -> 11.198268 | D116: =MAX(D105,F105,H105,J105,L105,N105,P105,R105,T105,V105) -> 138.61802 | E116: =MAX(D107,F107,H107,J107,L107,N107,P107,R107,T107,V107) -> 572.88626 | I116: макс | J116: 11.002648 | K116: 16.938115
B117: разброс | C117: =C116-C115 -> 0.48654764 | D117: =D116-D115 -> 217.54443 | E117: =E116-E115 -> 169.09578 | I117: разброс | J117: 0.0081705146 | K117: 4.3467955
C120: Вывод: Оценки стали менее точными, разброс очень большой. a1 и a0 заметно сместились (особенно a₀). Надёжность выводов низкая.

Sheet 4.
A1: Ui = ui * сигма | B1: при i=1 | D1: Ui = d * Ui-1 + c * ui | E1: при i=2, 3, …
H2: 1 экс | I2: 2 экс | J2: 3 экс | K2: 4 экс | L2: 5 экс | M2: 6 экс | N2: 7 экс | O2: 8 экс | P2: 9 экс | Q2: 10 экс
A3: а0= | B3: 14 | C3: X1 | D3: = | E3: 212 | F3: Y1 | G3: = | H3: =$B$3+$B$4*$E3+U3 -> 2345.7469 | I3: =$B$3+$B$4*$E3+V3 -> 2330.6846 | J3: =$B$3+$B$4*$E3+W3 -> 2341.1264 | K3: =$B$3+$B$4*$E3+X3 -> 2349.5931 | L3: =$B$3+$B$4*$E3+Y3 -> 2337.5393 | M3: =$B$3+$B$4*$E3+Z3 -> 2349.4341 | N3: =$B$3+$B$4*$E3+AA3 -> 2353.9434 | O3: =$B$3+$B$4*$E3+AB3 -> 2326.8996 | ... Q3: =$B$3+$B$4*$E3+AD3 -> 2337.4802 | S3: 1 | U3: ='Станд.норм.распр.'!B3*$B$5 -> -0.25305326 | V3: ='Станд.норм.распр.'!C3*$B$5 -> -15.315431 | W3: ='Станд.норм.распр.'!D3*$B$5 -> -4.8736388 | X3: ='Станд.норм.распр.'!E3*$B$5 -> 3.5931373 | Y3: ='Станд.норм.распр.'!F3*$B$5 -> -8.4607158 | Z3: ='Станд.норм.распр.'!G3*$B$5 -> 3.4341349 | AA3: ='Станд.норм.распр.'!H3*$B$5 -> 7.943388 | AB3: ='Станд.норм.распр.'!I3*$B$5 -> -19.100426 | ... AD3: ='Станд.норм.распр.'!K3*$B$5 -> -8.5197667
A4: а1= | B4: 11 | C4: X2 | D4: = | E4: 780 | F4: Y2 | G4: = | H4: =$B$3+$B$4*$E4+U4 -> 8593.4722 | I4: =$B$3+$B$4*$E4+V4 -> 8592.5194 | J4: =$B$3+$B$4*$E4+W4 -> 8597.6933 | K4: =$B$3+$B$4*$E4+X4 -> 8599.7061 | L4: =$B$3+$B$4*$E4+Y4 -> 8592.1231 | M4: =$B$3+$B$4*$E4+Z4 -> 8592.9703 | N4: =$B$3+$B$4*$E4+AA4 -> 8595.3991 | O4: =$B$3+$B$4*$E4+AB4 -> 8586.4046 | ... Q4: =$B$3+$B$4*$E4+AD4 -> 8591.8508 | S4: 2 | U4: =$B$6*U3+$B$7*'Станд.норм.распр.'!B4 -> -0.52784571 | V4: =$B$6*V3+$B$7*'Станд.норм.распр.'!C4 -> -1.4806187 | W4: =$B$6*W3+$B$7*'Станд.норм.распр.'!D4 -> 3.6932659 | X4: =$B$6*X3+$B$7*'Станд.норм.распр.'!E4 -> 5.7061317 | Y4: =$B$6*Y3+$B$7*'Станд.норм.распр.'!F4 -> -1.8768903 | Z4: =$B$6*Z3+$B$7*'Станд.норм.распр.'!G4 -> -1.0297452 | AA4: =$B$6*AA3+$B$7*'Станд.норм.распр.'!H4 -> 1.3990654 | AB4: =$B$6*AB3+$B$7*'Станд.норм.распр.'!I4 -> -7.5954381 | ... AD4: =$B$6*AD3+$B$7*'Станд.норм.распр.'!K4 -> -2.1491894
A5: сигма= | B5: 9 | C5: X3 | D5: = | E5: 280 | F5: Y3 | G5: = | H5: =$B$3+$B$4*$E5+U5 -> 3091.8203 | I5: =$B$3+$B$4*$E5+V5 -> 3092.1039 | J5: =$B$3+$B$4*$E5+W5 -> 3098.6508 | K5: =$B$3+$B$4*$E5+X5 -> 3103.0907 | L5: =$B$3+$B$4*$E5+Y5 -> 3094.1816 | M5: =$B$3+$B$4*$E5+Z5 -> 3093.3305 | N5: =$B$3+$B$4*$E5+AA5 -> 3098.5935 | O5: =$B$3+$B$4*$E5+AB5 -> 3086.8219 | ... Q5: =$B$3+$B$4*$E5+AD5 -> 3090.82 | S5: 3 | U5: =$B$6*U4+$B$7*'Станд.норм.распр.'!B5 -> -2.1797041 | V5: =$B$6*V4+$B$7*'Станд.норм.распр.'!C5 -> -1.8961362 | W5: =$B$6*W4+$B$7*'Станд.норм.распр.'!D5 -> 4.6508325 | X5: =$B$6*X4+$B$7*'Станд.норм.распр.'!E5 -> 9.0906534 | Y5: =$B$6*Y4+$B$7*'Станд.норм.распр.'!F5 -> 0.18162146 | Z5: =$B$6*Z4+$B$7*'Станд.норм.распр.'!G5 -> -0.66950605 | AA5: =$B$6*AA4+$B$7*'Станд.норм.распр.'!H5 -> 4.5935069 | AB5: =$B$6*AB4+$B$7*'Станд.норм.распр.'!I5 -> -7.1780653 | ... AD5: =$B$6*AD4+$B$7*'Станд.норм.распр.'!K5 -> -3.1799988
A6: d= | B6: 0.5 | C6: X4 | D6: = | E6: 888 | F6: Y4 | G6: = | H6: =$B$3+$B$4*$E6+U6 -> 9778.231 | I6: =$B$3+$B$4*$E6+V6 -> 9787.4835 | J6: =$B$3+$B$4*$E6+W6 -> 9784.242 | K6: =$B$3+$B$4*$E6+X6 -> 9785.6312 | L6: =$B$3+$B$4*$E6+Y6 -> 9783.0498 | M6: =$B$3+$B$4*$E6+Z6 -> 9782.5398 | N6: =$B$3+$B$4*$E6+AA6 -> 9791.034 | O6: =$B$3+$B$4*$E6+AB6 -> 9779.3427 | ... Q6: =$B$3+$B$4*$E6+AD6 -> 9780.5426 | S6: 4 | U6: =$B$6*U5+$B$7*'Станд.норм.распр.'!B6 -> -3.7689642 | V6: =$B$6*V5+$B$7*'Станд.норм.распр.'!C6 -> 5.4835147 | W6: =$B$6*W5+$B$7*'Станд.норм.распр.'!D6 -> 2.241986 | X6: =$B$6*X5+$B$7*'Станд.норм.распр.'!E6 -> 3.6311754 | Y6: =$B$6*Y5+$B$7*'Станд.норм.распр.'!F6 -> 1.0497774 | Z6: =$B$6*Z5+$B$7*'Станд.норм.распр.'!G6 -> 0.53980798 | AA6: =$B$6*AA5+$B$7*'Станд.норм.распр.'!H6 -> 9.033981 | AB6: =$B$6*AB5+$B$7*'Станд.норм.распр.'!I6 -> -2.6573167 | ... AD6: =$B$6*AD5+$B$7*'Станд.норм.распр.'!K6 -> -1.4574223
A7: c= | B7: 3 | C7: X5 | D7: = | E7: 314 | F7: Y5 | G7: = | H7: =$B$3+$B$4*$E7+U7 -> 3466.1276 | I7: =$B$3+$B$4*$E7+V7 -> 3470.9495 | J7: =$B$3+$B$4*$E7+W7 -> 3470.5101 | K7: =$B$3+$B$4*$E7+X7 -> 3469.7048 | L7: =$B$3+$B$4*$E7+Y7 -> 3469.1637 | M7: =$B$3+$B$4*$E7+Z7 -> 3468.0055 | N7: =$B$3+$B$4*$E7+AA7 -> 3471.7174 | O7: =$B$3+$B$4*$E7+AB7 -> 3467.771 | ... Q7: =$B$3+$B$4*$E7+AD7 -> 3471.8758 | S7: 5 | U7: =$B$6*U6+$B$7*'Станд.норм.распр.'!B7 -> -1.8724359 | V7: =$B$6*V6+$B$7*'Станд.норм.распр.'!C7 -> 2.9495007 | W7: =$B$6*W6+$B$7*'Станд.норм.распр.'!D7 -> 2.5101359 | X7: =$B$6*X6+$B$7*'Станд.норм.распр.'!E7 -> 1.7048317 | Y7: =$B$6*Y6+$B$7*'Станд.норм.распр.'!F7 -> 1.1636643 | Z7: =$B$6*Z6+$B$7*'Станд.норм.распр.'!G7 -> 0.0055275251 | AA7: =$B$6*AA6+$B$7*'Станд.норм.распр.'!H7 -> 3.7173536 | AB7: =$B$6*AB6+$B$7*'Станд.норм.распр.'!I7 -> -0.22899059 | ... AD7: =$B$6*AD6+$B$7*'Станд.норм.распр.'!K7 -> 3.8758377
C8: X6 | D8: = | E8: 780 | F8: Y6 | G8: = | H8: =$B$3+$B$4*$E8+U8 -> 8590.5804 | I8: =$B$3+$B$4*$E8+V8 -> 8590.0081 | J8: =$B$3+$B$4*$E8+W8 -> 8596.9916 | K8: =$B$3+$B$4*$E8+X8 -> 8592.0254 | L8: =$B$3+$B$4*$E8+Y8 -> 8596.3888 | M8: =$B$3+$B$4*$E8+Z8 -> 8594.5757 | N8: =$B$3+$B$4*$E8+AA8 -> 8595.2305 | O8: =$B$3+$B$4*$E8+AB8 -> 8591.4947 | ... Q8: =$B$3+$B$4*$E8+AD8 -> 8598.6893 | S8: 6 | U8: =$B$6*U7+$B$7*'Станд.норм.распр.'!B8 -> -3.4195955 | V8: =$B$6*V7+$B$7*'Станд.норм.распр.'!C8 -> -3.9918903 | W8: =$B$6*W7+$B$7*'Станд.норм.распр.'!D8 -> 2.9915741 | X8: =$B$6*X7+$B$7*'Станд.норм.распр.'!E8 -> -1.9746006 | Y8: =$B$6*Y7+$B$7*'Станд.норм.распр.'!F8 -> 2.3888322 | Z8: =$B$6*Z7+$B$7*'Станд.норм.распр.'!G8 -> 0.57572155 | AA8: =$B$6*AA7+$B$7*'Станд.норм.распр.'!H8 -> 1.2304604 | AB8: =$B$6*AB7+$B$7*'Станд.норм.распр.'!I8 -> -2.5052954 | ... AD8: =$B$6*AD7+$B$7*'Станд.норм.распр.'!K8 -> 4.6892745
C9: X7 | D9: = | E9: 993 | F9: Y7 | G9: = | H9: =$B$3+$B$4*$E9+U9 -> 10939.176 | I9: =$B$3+$B$4*$E9+V9 -> 10932.252 | J9: =$B$3+$B$4*$E9+W9 -> 10941.202 | K9: =$B$3+$B$4*$E9+X9 -> 10939.431 | L9: =$B$3+$B$4*$E9+Y9 -> 10938.953 | M9: =$B$3+$B$4*$E9+Z9 -> 10937.07 | N9: =$B$3+$B$4*$E9+AA9 -> 10939.344 | O9: =$B$3+$B$4*$E9+AB9 -> 10937.595 | ... Q9: =$B$3+$B$4*$E9+AD9 -> 10939.937 | S9: 7 | U9: =$B$6*U8+$B$7*'Станд.норм.распр.'!B9 -> 2.1762798 | V9: =$B$6*V8+$B$7*'Станд.норм.распр.'!C9 -> -4.7476487 | W9: =$B$6*W8+$B$7*'Станд.норм.распр.'!D9 -> 4.2016725 | X9: =$B$6*X8+$B$7*'Станд.норм.распр.'!E9 -> 2.4305489 | Y9: =$B$6*Y8+$B$7*'Станд.норм.распр.'!F9 -> 1.9525152 | Z9: =$B$6*Z8+$B$7*'Станд.норм.распр.'!G9 -> 0.069762809 | AA9: =$B$6*AA8+$B$7*'Станд.норм.распр.'!H9 -> 2.3436021 | AB9: =$B$6*AB8+$B$7*'Станд.норм.распр.'!I9 -> 0.59496237 | ... AD9: =$B$6*AD8+$B$7*'Станд.норм.распр.'!K9 -> 2.9367729
